Workbook

Sheet 摘要效果-打分标准
A1: 需求文档：https://ione.rnd.huawei.com/tcloud/main/#/req/viewSr?serialNo=SR000K2TFN
A3: # 具体打分细则
A4: 独立评估以下三个维度，不要受格式和排版的影响，输出结果为1~5范围内的打分：
A5: 1. 准确性
A6: - 独立评估摘要是否忠实于原文事实。核心要求是“不瞎编、不篡改”。
A7: - **以下情况视严重程度扣分：**
A8: 1.1 幻觉：捏造原文不存在的内容。
A9: 1.2 事实错误：错误理解原文内容，将与A相关的内容套到了B上。
A10: 1.3 实体提取错误：关键的专有名词、人名、数值提取错误。
A11: -如果原文存在ASR错误或错别字导致理解有困难，不扣分
A12: 1.4 逻辑错乱：错误解释前因后果或推导过程。
A13: 1.5 其它问题：其它摘要和原文不一致，或与事实不符的问题。
... A49: 4.4 语言风格严重突变（如中英文异常夹杂）。

Sheet 竞品对比
A1: 序号 | B1: 分工 | C1: 原文 | D1: A产品 | E1: 准确性 | F1: 相关性 | G1: 通顺性 | H1: 其它问题 | I1: MOS | J1: 备注 | K1: B产品 | L1: 准确性 | M1: 相关性 | N1: 通顺性 | O1: 其它问题 | P1: MOS | Q1: 备注 | R1: C产品 | S1: 准确性 | T1: 相关性 | U1: 通顺性 | V1: 其它问题 | W1: MOS | X1: 备注
A2: 1 | B2: 黄文涛 | C2: • 发言者 1 00:21 最近呢霍伊斯根主席各位朋友，各位同事，我们所处的是一个更加变乱交织的世界。大家都关心这个世界今后向何处去。借用今年慕安会报告的主题来回答的话，那就是走向多极化。80年前联合国成立时，只有51个会员国，到今天是193个国家，共乘一艘大船。多极化的世界既是历史的必然，也正在成为现实。多极化是否会带来动荡失序，冲突对抗是否意味着大国主导弱肉强食。中国给出的答案是我们应当推动平等有序的世界多极化。这是习近平主席提出的又一个重大主张，也是我们对多极世界真诚的期许。中国必将是多极体系中的确定性因素。将坚定做变革世界中的建设性力量。在此我表达4点看法。一是应当倡导平等相待，列强争霸曾给人类带来灾难。两次世界大战殷鉴不远，殖民体系也罢， • 发言者 1 01:58 中心外围体系也罢，不平等的秩序注定土崩瓦解。世界各国独立自主，风起云涌，国际关系民主法不可阻挡。坚持权利平等机会平等规则平等，应当成为建设多极世界的基本原则。正是秉+D5持这样的原则，中国主张大小国家一律平等，呼吁提升发展中国家在国际体系中的代表性和发言权。这不会导致西方的缺失，而将促进世界的正和慕安会近年来邀请更多全球南方国家出席会议，这是明智之举。每一个国家的声音都应该得到倾听。每一个国家都可以在多极格局中找到自身的位置，发挥自己的作用。二是应当尊重国际法治。中国有句古话没有规矩不成方圆， • 发言者 1 03:06 联合国宪章宗旨和原则是处于国际关系的根本遵循。也是建设多极世界的重要基石。当今世界乱象频出，一个重要原因就是有些国家迷信实力至上，打开了丛林法则的潘多拉盒子。实际上国家不论大小强弱，都是国际法治的利益攸关法。多极格局不能是无序的状态。如果没有了规矩，昨天在餐桌上明天就可能在菜单里大国要带头讲诚信，讲法治，坚决摒弃言行不一。零和博弈。正是基于这样的观点，中国坚定维护国际法治权威，积极履行国际责任和义务。我们加入了几乎所有普遍性的政府间国际组织和600多项国际公约。我们从不搞例外主义， • 发言者 1 04:18 更不搞合则用，不合则弃。我们为当今不确定的世界提供了最大的确定性。我要强调的是在遵守国际法上不能搞双重标准，要尊重各国的主权和领土完整，就应该支持中国实现完全统一。三是要践行多边主义。面对层出不穷的全球性挑战，没有哪一个国家能够独善其身，搞本国优先只会造成各方的多数。联合国是践行多边主义，推进全球治理的核心平台。已经为各国遮风挡雨。80年。未来的多极世界更加需要联合国对于这座大厦，我们应该固本强基，而不是拆梁毁柱。对于治理全球难题应当共担责任， • 发言者 1 05:23 而不是唯利是图。对于共同挑战应该团结应对，而不是阵营对抗。正是本着这样的理念，中国坚持真正的多边主义，倡导共商共建共享的全球治理观。我们坚定维护联合国的权威和地位，承担着超过20%的联合国的会费。我们切实履行巴黎协定，建成了世界上最大的清洁发电体系。我们还提出并落实全球发展倡议，全球安全倡议全球文明倡议，为完善全球治理提供公共产品。4是要坚持开放共赢。发展是破解各种难题的钥匙，多极世界应该是各国共同发展的世界。保护主义不是出路， • 发言者 1 06:28 滥加关税没有赢家。脱钩断链断的是机遇，小院高墙封的是自己。应当坚持开放合作，以普惠包容的经济全球化。来支撑平等有序的世界多极化。正是朝着这样的目标，中国坚定同各国共享发展机遇。有位澳大利亚的学者把中国称为赋能型大国，我认为很形象。去年中国GDP增长5%，对世界经济增长的贡献率接近30%。我们担当起全球经济增长的重要引擎，我们向世界释放超大规模的市场红利。中国愿推动高质量共建一带一路，而且同欧盟的门户全球门户的战略相互对接。赋能彼此也赋能世界。各位朋友， • 发言者 1 07:38 中方始终认为欧洲是多极世界的重要一极。中欧双方是伙伴而不是对手。今年是中欧建交50周年，中方愿意同欧方用好这一契机，深化战略沟通和互利合作，推动世界走向和平。安全繁荣进步的光明前景。谢谢各位。 • 发言者 2 08:44 Thankvery much and director wang yi for your speech and also thanking for clinging to the10min. Appreciate that. You mentioned the international order, and this is something thatalso in my introductory remarks, I highlighted the need to respect the un charter and喂see nowa IoT of questioning of this. • 发言者 2 09:08 喂seerussia invadingukraine.We haveseenfrom the americanPresident.These last weeks,where he threatened to use forceinvading greenland and panama andalso the the displacement of palestiniansand your country.Has been also accused of violating the law of the sea or also the universal declaration of human rights. • 发言者 2 09:34 Now you are traveling from here to new york to the security council. Do you continue to believe in the united nations? Do you believe in the charter of the un?and will you work also for reform of the un? The un charter? How high is that on your priority? • 发言者 1 10:03 嗯。我不愿意回答。周琦先生的提问，你的提问当中大概涉及到两个关键词，一个是秩序，一个是规则。那么说到秩序，这几年总有人说中国要改变秩序，中国要另起炉灶，但是我想现在再说这种话的人可能不会太多了。因为真正要挑战秩序，在毁约退群的国家出现了尤其欧洲的朋友们，你可能每天都在感受到阵阵袭来的寒意。而中国我们是在现行国际秩序中发展起来的，我们是这个秩序的受益者。我们要做的就是按照大多数国家的愿望，推动这个秩序朝着更加公正合理的方向去发展。谈到规则，大家可能对规则有不同的理解。但是我认为我们起码应该有一个共同的认知， • 发言者 1 11:16 那就是我们需要共同来维护。以联合国为核心的国际体系。共同遵守以联合国宪章宗旨和原则为基础的国际关系的基本准则。我想这应该是我们的最大的公约数。只要我们大家都认同这一点，有些人所说的双重标准就不会出现了，没有它存在的空间。很多重大的地区热点问题，就像刚才朱医生所谈到的，我们都有了判断的。同样的标准，中国意识到我们承担的国际责任和义务，我们愿意向世界提供更多的公共产品。习近平主席提出了一系列重大的倡议和主张，包括我刚才提到的全球发展倡议，全球安全倡议。全球文明倡议，我们是希望国际社会能够携起手来，共同来解决好当今日益严重的发展赤字。安全赤字， • 发言者 1 12:40 还有治理赤字。习主席还提出了一个重大的理念，那就是我们各国一起共同构建人类命运共同体。这是一个宏伟的目标。那么我们希望各国都能够超越历史文化社会制度意识形态的这种不同。我们以同舟共济的精神，共同来呵护好我们这个唯一人类可以居住的星球，我们共同来建设好命运与共的地球村。这既是我们中国我们共产党的国际主义的一种情怀，也是体现了天下为公。这一中华民族的优秀的文化的传统，已经得到了越来越多国家的理解认同和支持。而中国我们将会继续为践行好这些重要的理念来做出我们的努力。和贡献。 • 发言者 1 13:56 谢谢。 • 发言者 2 14:01 One of the topics here since22has been russia's invasion of ukraineat the msc just a few days before russia'sinvasion,you stated and I quoteThe sovereignty, independence and territorial integrity of any country should be respected and safeguarded because IT is a basic norm of international relations. Ukraine is no exception, so you confirmed the charter of the united nations now.Today,russia has become whatJohn mccainwants,saidhere at the munich security conference. • 发言者 2 14:39 China's gas station, I would add,it's a gas station with with anarmythis means you have a you have a IoT ofinfluenceon ukraine. Do you see AA possibility now that there is more pressure and finally more pressure to finish this war that from from yourend,you couldmaybe do something on your side of thegas station, • 发言者 2 15:11 and maybecutthe possibility of russia to supply gas to to your country or lower the price orStop some of the dual use goods that are coming there so thatthere's more pressure on russia to finally finish this war. • 发言者 1 15:32 中国同俄罗斯，我们是两大邻国，有着漫长的边界。两国关系。过去经历过一番曲折的经历。之后我们双方吸取教训，我们建立了结盟不对抗，不针对第三方的那么睦邻友好关系，进而我们增进了我们的战略互信，建立了全面战略伙伴关系。中国同俄罗斯之间的交往是正常的，国与国之间的交往刚才提到中国可不可以不从俄罗斯买油气了？我想问一句，如果中国不从俄罗斯买，哪个国家能够提供如此巨量的油气来满足中国民众的需求呢？那是不可能的，也是不保险的。 • 发言者 1 16:24 因为常常有的国家把经贸问题政治化，当做打压中国的工具，我们不会允许出现这样的情况，我们要为我们的人民负责任。但是中国在对待地区热点问题上是有我们的立场的。我们历来主张一切争端和冲突都应该通过对话寻求政治解决。因为武力和制裁不可能真正和彻底的解决问题，乌克兰问题上同样如此。从这场危机爆发的第2天开始，就是2022年2月25号，中方就提出了对话协商解决。习近平主席提出的4点主张是中国立场的最权威的阐释，那就是各国的主权领土完整应该得到尊重， • 发言者 1 17:25 联合国的宪章应该得到遵守。各国的合理安全关切应该得到重视。一切致力于和平的努力都应该得到支持。我们就是以此为遵循，在不断的推进我们的劝和促谈，哪怕呢有一点希望，我们就要做出我们的百倍的努力，我们派出的特使去各国斡旋。我们同巴西等南方国家发起了和平之友。那么中国的这些立场现在看随着时间的推移，应该说是公正的客观的。也是理性的务实的，体现了国际社会的最大的共识。任何冲突的终点都是谈判桌，历史最终一定是公正的。中方乐见一切。致力于和平的努力。包括这两天美国同俄罗斯达成的共识。 • 发言者 1 18:45 同时我们认为所有当事方包括利益攸关方，都应该适时的参与到这个和谈的进程当中。这场战事发生在欧洲大地上，欧洲更有必要为此发挥重要的作用，共同来解决好危机。的根源性的因素，共同来探讨欧洲的长治久安。找到大家都能够接受的。均衡有效可持续的，欧洲的安全的框架，谢谢。 • 发言者 2 19:37 We are we have run out of time, but I would at least very briefly ask you to give us a sneak preview of how you think the relationship between us and China will develop. • 发言者 1 19:53 这是一个大家都关心的问题，我要在这里首先告诉大家的是中国的对美政策保持着连续性和稳定性，我们不会轻易的翻烙饼。这体现了作为大国的战略定力和国际信誉。我们的对美政策就是习近平主席提出的三原则，相互尊重，和平共处。合作共赢。中国和美国我们制度确实不一样，这是我们各自人民做出的选择。如果想改造或者颠覆对方的话，那是不切实际的。正确的态度就是相互尊重。这是中美交往的一个前提。和平共处。更是理所当然。中美两个大国总不能冲突起来吧，因为那将殃及整个世界，所以还是要开展对话， • 发言者 1 20:58 加强交往，增进了解。建立信任。合作共赢，这是因为国际社会期待中美开展合作。全球性的挑战也需要中美携手来应对。当然这也是中美两个大国应当承担的国际责任。中方已经准备好了，我们愿意按照三原则同美方构建稳定健康可持续的双边关系，找到两个大国在这个星球上的正确相处之道。我们当然希望美方能够相向而行。但是如果美方不愿意，如果美方仍然还要对中国打压和遏制，那我们也别无选择，我们必将奉陪到底。我们必将坚定的维护中国的主权。中国的国家的尊严和我们的正当发展权利。必将坚决的回击。美方的单。单机和霸凌的这种行径。中国这样做也是为了维护国际的公平正义， • 发言者 1 22:35 为了维护国际关系的基本准则，中国人从来不信邪，不怕鬼。新中国就是在战胜各种艰难险阻中发展。壮大起来的。中国有句古话叫做天行健。军事自强不息。中国还有一句话，说得很形象，那就是他强任他强，清风拂山岗。他横任他横明月照大江。任尔东西南北风。我自泰然处之。岿然不动。这几句话可能翻译起来。不容易，唉可能又会出来很多翻译的版本，大家可以相互切磋。也可以找deep seek来帮一帮忙。总之我们对这个世界的前途是充满信心的。同样我们对中美关系的未来也是充满信心的。中美两国只有一个我们共同努力的方向， • 发言者 1 24:08 那就是刚才我反复谈到的相互尊重，和平共处，合作共赢，这也是国际社会最大的期待，谢谢。 • 发言者 2 24:30 very much.Also, for this proverb,喂see if we have chat gp or so, translating IT. But I thought the british, the english translation,喂got was pretty good. . Thank you for being. Yeah, I hope I sincerely hope. Also, you can usethe possibility ofmunich to meet withrepresentatives of the new us administration, • 发言者 2 24:50 and IT would be very good that what you are,what you are also proposing. More talks and discussion on these issues withmaterialS here in munich. I wish you again. Good luck to you on your trip to new york and thank you for being such a goodguest here to the munich security conference. • 发言者 2 25:12 Thank you for this all the best. . | D2: # 发布会概况 本次发言围绕当前国际局势的多极化发展趋势展开，重点阐述了中国在推动平等有序的世界多极化、维护国际法治、践行多边主义和坚持开放共赢等方面的立场与主张。发言者以慕安会报告主题为引，结合中国外交政策和全球治理实践，回应了关于国际秩序、俄乌冲突及中美关系等热点问题。整体基调强调中国作为多极体系中的确定性因素，致力于建设性参与国际事务，维护世界和平与繁荣。 # 核心信息 - 中国主张推动**平等有序的世界多极化**，这是习近平主席提出的重大主张 - 中国是联合国会费承担国中**超过20%的联合国会费**承担者 - 中国加入了**几乎所有普遍性的政府间国际组织**和**600多项国际公约** - 中国建成**世界上最大的清洁发电体系** - 中国GDP增长**5%**，对世界经济增长贡献率接近**30%** - 中国提出并落实**全球发展倡议**、**全球安全倡议**、**全球文明倡议** - 中国与俄罗斯建立**结盟不对抗不针对第三方的睦邻友好关系**，并发展为**全面战略伙伴关系** - 中国对美政策坚持**相互尊重、和平共处、合作共赢**的三原则 # 官方表态 > "中国必将是多极体系中的确定性因素。将坚定做变革世界中的建设性力量。" > "我们从不搞例外主义，更不搞合则用，不合则弃。" > "中国同俄罗斯之间的交往是正常的，国与国之间的交往。" > "我们不会允许出现这样的情况，我们要为我们的人民负责任。" > "中国有句古话叫做天行健，君子以自强不息。" > "中国当然希望美方能够相向而行。但是如果美方不愿意，如果美方仍然还要对中国打压和遏制，那我们也别无选择，我们必将奉陪到底。" # Q&A环节 问 → "中国同俄罗斯的交往是否违背联合国宪章？中国是否愿意对俄罗斯施加压力结束俄乌战争？" 答 → 中国与俄罗斯建立的是结盟不对抗不针对第三方的睦邻友好关系，两国交往是正常的国与国之间交往。中国认为任何冲突的终点都是谈判桌，主张通过对话寻求政治解决。中国不会允许经贸问题被政治化，作为打压中国的工具。中国在乌克兰问题上始终主张尊重各国主权领土完整，遵守联合国宪章，重视各国合理安全关切，支持一切和平努力。 问 → "如何看待中国在国际秩序和规则方面的立场？" 答 → 中国是在现行国际秩序中发展起来的，是这个秩序的受益者。中国要做的就是推动这个秩序朝着更加公正合理的方向发展。中国主张共同维护以联合国为核心的国际体系，共同遵守以联合国宪章宗旨和原则为基础的国际关系基本准则。中国提出了一系列重大倡议和主张，包括全球发展倡议、全球安全倡议、全球文明倡议，致力于解决发展赤字、安全赤字和治理赤字问题。 问 → "中美关系未来将如何发展？" 答 → 中国的对美政策保持连续性和稳定性，不会轻易改变。中国坚持相互尊重、和平共处、合作共赢的三原则。中美两个大国应当承担国际责任，共同应对全球性挑战。中国愿意按照三原则同美方构建稳定健康可持续的双边关系。如果美方仍然对中国打压和遏制，中国必将坚定维护主权、国家尊严和正当发展权利，坚决回击美方的单边和霸凌行径。 | E2: 4 | F2: 4 | G2: 5 | I2: =(E2+F2+G2)/3 -> 4.3333333 | J2: 1.2：摘要两次将中俄关系表述为“结盟不对抗不针对第三方”，但原文实际写的是“不结盟、不对抗、不针对第三方”。遗漏“不”字直接改变了中国对俄关系定位，属于较严重的事实性错误；2.1：遗漏了欧洲作为多极世界重要一极、中欧建交50周年以及深化中欧战略沟通和互利合作等较重要内容。 | K2: 纪要 中国倡导平等有序的世界多极化 主张构建人类命运共同体 引言：世界向何处去？中国提出多极化愿景 在2026年慕尼黑安全会议（MSC）上，中国代表王毅就全球秩序、国际规则与多极化未来发表重要讲话。面对一个“变乱交织”的世界，他指出，当今世界正走向多极化，这是历史必然，也已成为现实。中国主张推动“平等有序的世界多极化”，强调自身将作为变革中的“确定性因素”和“建设性力量”。 此次讲话正值中欧建交50周年之际，中方重申欧洲是多极世界的重要一极，中欧应是伙伴而非对手，并呼吁深化战略沟通与互利合作，共同推动世界走向和平、安全、繁荣与进步。 四大主张：构建公正合理多极世界的中国方案 一、倡导平等相待，反对霸权与不平等秩序 发言人指出，列强争霸曾给人类带来深重灾难，殖民体系与“中心—外围”结构等不平等秩序终将土崩瓦解。国际关系民主化不可阻挡，权利平等、机会平等、规则平等应成为多极世界的基本原则。 中国坚持大小国家一律平等，主张提升发展中国家在国际体系中的代表性和发言权。这一立场不会导致西方的“缺失”，反而有助于实现“正和”共赢。近年来慕安会邀请更多全球南方国家参会，被评价为“明智之举”。 二、尊重国际法治，维护联合国宪章权威 发言人引用中国古语“没有规矩不成方圆”，强调联合国宪章宗旨和原则是处理国际关系的根本遵循，也是建设多极世界的重要基石。 当前世界乱象频出，根源在于某些国家迷信“实力至上”，打开了“丛林法则的潘多拉盒子”。若无规则约束，“昨天在餐桌上，明天就可能在菜单里”。大国应带头讲诚信、守法治，避免言行不一。中国已加入几乎所有普遍性政府间国际组织及600多项国际公约，从不搞“合则用、不合则弃”的例外主义。 特别强调：遵守国际法不能搞双重标准。尊重各国主权和领土完整，就应支持中国实现完全统一。 三、践行真正多边主义，巩固联合国核心地位 面对全球性挑战，任何国家都无法独善其身。搞“本国优先”只会造成多方皆输。联合国作为全球治理的核心平台，已为各国“遮风挡雨”80年，未来更需加强。 中国坚持共商共建共享的全球治理观，承担超过20%的联合国会费，切实履行《巴黎协定》，建成全球最大清洁发电体系。同时提出并落实三大倡议： 全球发展倡议 全球安全倡议 全球文明倡议 这些举措旨在为完善全球治理提供公共产品，应对发展赤字、安全赤字与信任赤字。 四、坚持开放共赢，以发展破解全球难题 发展是破解各种难题的钥匙。多极世界应是各国共同发展的世界。保护主义、滥施关税、脱钩断链、“小院高墙”皆非出路，只会切断机遇、封闭自我。 中国致力于普惠包容的经济全球化，愿与各国共享发展机遇。去年GDP增长5%，对全球经济增长贡献率接近30%，被誉为“赋能型大国”。中国将继续推动高质量共建“一带一路”，并与欧盟“全球门户”战略对接，实现彼此赋能、共同赋能世界。 回应质疑：关于乌克兰危机与中俄关系 针对外界对中国与俄罗斯关系的关切，发言人明确表示，中俄是邻国，建立了“不结盟、不对抗、不针对第三方”的全面战略伙伴关系，双边交往属正常国家关系。 对于“中国是否可停止进口俄油气以施压俄罗斯结束战争”的提问，发言人反问：“哪个国家能提供如此巨量能源满足中国需求？”强调能源供应关乎民生与国家安全，中国必须对人民负责，不会允许他国将能源问题政治化。 在乌克兰问题上，中国自2022年2月25日起即主张通过对话协商政治解决。习近平主席提出的四点主张构成中国立场的核心： 各国主权和领土完整应受尊重 联合国宪章宗旨和原则必须遵守 各方合理安全关切应被重视 一切和平努力都应得到支持 中方派出特使斡旋，并与巴西等国发起“和平之友”倡议。相关立场被视为公正、客观、务实，正逐渐成为国际社会最大共识。 发言人强调，所有当事方和利益攸关方都应适时参与和谈。战事发生在欧洲，欧洲更应发挥重要作用，共同探讨建立均衡、有效、可持续的欧洲安全框架。 中美关系：坚持三原则 寻求正确相处之道 面对中美关系前景之问，发言人重申中国对美政策具有连续性与稳定性，体现大国战略定力与国际信誉。 中方坚持习近平主席提出的对美三原则： 相互尊重：制度差异是各自人民选择的结果，不应试图改造或颠覆对方 和平共处：两大国冲突将殃及全球，必须加强对话、增进了解、建立信任 合作共赢：全球挑战需中美携手应对，这是两国应尽的国际责任 中国愿同美方构建稳定、健康、可持续的双边关系。但若美方继续推行打压遏制政策，中方“别无选择，必将奉陪到底”，坚定维护国家主权、尊严与发展权利，坚决回击单边霸凌行径。 发言人引用中国古语表达立场：“天行健，君子以自强不息”；“他强任他强，清风拂山岗；他横任他横，明月照大江”；“任尔东西南北风，我自岿然不动。” 表明中国不信邪、不怕鬼，有信心应对任何挑战。 结语：信心源于理念 共同守护地球家园 发言人最后强调，中国提出构建“人类命运共同体”是宏伟目标，体现中国共产党的国际主义情怀与中华民族“天下为公”的文化传统。该理念已获得越来越多国家的理解、认同与支持。 中国将继续为践行这一理念作出努力与贡献。尽管前路复杂，但对世界前途充满信心，对中美关系未来亦抱有信心。唯一方向就是回归相互尊重、和平共处、合作共赢的正轨——这也是国际社会的最大期待。 会议信息摘要 标题：2026-03-21 10:26:28 文件 开始时间：2026年3月21日 10:26 持续时间：00:25:27 场合：慕尼黑安全会议（MSC） 主要发言人：王毅 语言使用：简体中文为主，穿插英文互动 后续行程：发言后前往纽约出席联合国安理会会议 注：部分外方提问中提及的数据与事实（如美国威胁入侵格林兰、巴拿马等）未获独立证实，摘要中标注来源为“提问内容”，不代表事实确认。涉及中国被指控“违反海洋法”“人权宣言”等内容，中方未予承认，视为争议议题保留原意呈现。 章节 00:00:08 多极化世界的必然趋势与中国立场 发言人阐述当前世界正走向多极化的历史趋势，强调中国主张推动平等有序的世界多极化，并坚定做变革中的建设性力量。指出多极化不应导致失序与对抗，而应以平等、法治、多边主义和开放共赢为基础。 00:02:33 倡导国际关系中的平等相待原则 提出应坚持权利、机会和规则平等，反对不平等的国际秩序。中国主张大小国家一律平等，支持提升发展中国家在国际体系中的代表性和发言权，推动国际关系民主化，促进全球正和而非零和博弈。 00:03:10 尊重国际法治与联合国宪章权威 强调联合国宪章宗旨和原则是国际关系的根本遵循，反对实力至上和丛林法则。中国坚定维护国际法治，加入大量国际组织与公约，反对双重标准，呼吁共同遵守国际法，为世界提供确定性。 00:04:20 践行真正的多边主义与全球治理责任 面对全球性挑战，任何国家无法独善其身。联合国是多边主义核心平台，应固本强基而非削弱。中国坚持共商共建共享的治理观，承担高额会费，履行气候承诺，并提出三大全球倡议，为全球治理提供公共产品。 00:06:06 坚持开放共赢推动共同发展 发展是破解难题的钥匙，多极世界应是各国共同发展的世界。反对保护主义、脱钩断链和小院高墙。中国作为赋能型大国，贡献近三成世界经济增长，愿通过‘一带一路’等合作机制共享发展机遇。 00:07:28 中欧关系与多极世界中的合作前景 中方视欧洲为多极世界重要一极，强调中欧是伙伴而非对手。值此中欧建交50周年之际，愿深化战略沟通与互利合作，共同推动世界走向和平、安全、繁荣与进步。 00:09:48 回应国际秩序质疑：中国维护现行体系 针对外界对中国挑战国际秩序的误解，发言人澄清中国是现行国际秩序的受益者，致力于推动其向更公正合理方向发展。强调应以联合国为核心，共同维护国际规则，消除双重标准。 00:11:51 构建人类命运共同体的理念与实践 中国提出构建人类命运共同体的宏伟目标，倡导超越历史文化、社会制度和意识形态差异，以同舟共济精神守护地球家园。该理念体现中国共产党的国际主义情怀和中华优秀传统文化，已获广泛认同。 00:15:22 乌克兰危机立场：劝和促谈与中国角色 中国与俄罗斯保持正常国家关系，不结盟、不对抗。在乌克兰问题上，中方自危机爆发次日起即主张政治解决，提出四点主张并积极斡旋，发起‘和平之友’倡议，推动建立均衡、有效、可持续的欧洲安全框架。 00:19:43 中美关系的未来：三原则与战略定力 中国对美政策坚持相互尊重、和平共处、合作共赢三原则，保持连续性与稳定性。呼吁美方相向而行，若遭打压遏制，中国将坚决维护主权与发展权利，展现‘他强任他强，清风拂山岗’的战略自信。 | L2: 3 | M2: 4 | N2: 5 | P2: =(L2+M2+N2)/3 -> 4 | Q2: 1.1：摘要称讲话发生在“2026年慕尼黑安全会议”，但原始记录未提供会议年份；同时原文提到“今年是中欧建交50周年”，据此也不能支持2026年的判断，属于无依据补充；1.3：摘要将原文的“发展赤字、安全赤字、治理赤字”错误写成“发展赤字、安全赤字与信任赤字”，关键术语提取错误；1.2：摘要称能源供应“关乎民生与国家安全”，原文主要表达中国需要满足民众的巨大油气需求、保障供应可靠并对人民负责，未明确提出“国家安全”，存在一定程度的扩展解释；2.3：摘要前半部分已经按四大主张、中俄关系、乌克兰危机和中美关系进行了完整总结，后续“章节”部分又按照时间顺序重复概括同一批内容，整体重复比例超过30%，存在较明显冗余。 | R2: 总结 安理会报告主题与世界格局 今年安理会报告主题为“走向多极化”。 联合国成立时11个会员国，当前为193个国家。 多极化世界是历史必然且正在成为现实。 中国对多极化世界的主张：平等有序的世界多极化 中国的角色定位：中国是多极体系中的确定性因素，坚定做变革世界中的建设性力量。 核心关切：针对“国际化是否会带来动荡、失序、冲突、对抗？是否意味着大国主导、弱肉强食？”的问题，中国主张推动平等有序的世界多极化。 中国关于建设平等有序多极世界的四点看法 一是应当倡导平等相待 历史教训：列强争霸曾带来灾难（两次世界大战），不平等秩序（殖民体系、中心外围体系）注定瓦解。 时代趋势：世界各国独立自主风起云涌，国际关系民主化不可阻挡。 基本原则：坚持权利平等、机会平等、规则平等。 中国实践：主张大小国家一律平等，呼吁提升发展中国家在国际体系中的代表性和发言权，认为这将促进世界正和而非导致西方缺失。 积极现象：安理会近年来邀请更多全球南方国家出席会议是明智之举，每个国家的声音都应被倾听，每个国家都能在多极格局中找到位置、发挥作用。 二是应当尊重国际法治 重要性：“没有规矩不成方圆”，联合国宪章宗旨和原则是处理国际关系的根本遵循，也是建设多极世界的重要基石。 乱象原因：有些国家迷信实力至上，打开丛林法则的潘多拉盒子。 基本认知：国家不论大小强弱，都是国际法治的利益攸关方；多极格局不能是无序状态。 大国责任：大国要带头讲诚信、讲法治，坚决摒弃言行不一、零和博弈。 中国实践：坚定维护国际法治权威，积极履行国际责任和义务；加入几乎所有普遍性政府间国际组织和600多项国际公约；从不搞例外主义，不搞合则用、不合则弃，为不确定的世界提供最大确定性。 强调：在遵守国际法上不能搞双重标准；要尊重各国的主权和领土完整，就应该支持中国实现完全统一。 三是践行多边主义 背景：面对全球性挑战，没有国家能独善其身，“本国优先”会造成多方受损。 联合国的作用：是践行多边主义、推进全球治理的核心平台，未来多极世界更需要联合国。 正确态度：对联合国应固本强基而非拆梁；治理全球难题应共担责任而非唯利是图；应对共同挑战应团结应对而非阵营对抗。 中国实践：坚持真正的多边主义，倡导共商、共建、共享的全球治理观；坚定维护联合国权威和地位，承担超过20%的联合国会费；切实履行《巴黎协定》，建成世界上最大的清洁发电体系；提出并落实全球发展倡议、全球安全倡议、全球文明倡议，为完善全球治理提供公共产品。 四是坚持开放共赢 发展的重要性：发展是破解各种难题的钥匙，多极世界应是各国共同发展的世界。 错误做法：保护主义不是出路，滥加关税没有赢家，“脱钩断链”断的是机遇，“小院高墙”封的是自己。 正确方向：坚持开放合作，以普惠包容的经济全球化支撑平等有序的世界多极化。 中国实践：坚定同各国共享发展机遇；去年中国GDP增长5%，对世界经济增长的贡献率接近30%，担当全球经济增长重要引擎，释放超大规模市场红利；愿推动高质量共建“一带一路”，并同欧盟的“全球门户”战略相互对接，赋能彼此和世界。 中国对中欧关系的看法 中方始终认为欧洲是多极世界的重要一极。 中欧双方是伙伴而不是对手。 今年是中欧建交50周年，中方愿同欧方用好此契机，深化战略沟通和互利合作，推动世界走向和平、安全、繁荣、进步的光明前景。 关于国际秩序与规则的回应 中国与国际秩序：中国是现行国际秩序的受益者，并非要改变秩序或另起炉灶，而是推动秩序朝着更加公正合理的方向发展。真正挑战秩序、毁约退群的另有其国。 共同规则认知：应共同维护以联合国为核心的国际体系，共同遵守以联合国宪章宗旨和原则为基础的国际关系基本准则，这是最大公约数。如此，双重标准便无存在空间，地区热点问题判断可依据同样标准。 中国的国际责任：中国意识到承担的国际责任和义务，愿提供更多公共产品。习近平主席提出全球发展倡议、全球安全倡议、全球文明倡议，旨在解决发展赤字、安全赤字、治理赤字；提出构建人类命运共同体理念，希望各国超越差异，以同舟共济精神建设命运与共的地球村，这体现了中国共产党的国际主义情怀和中华民族“天下为公”的优秀文化传统，已得到越来越多国家理解、认同和支持。中国将继续为此努力贡献。 关于乌克兰问题的立场 中俄关系：中俄是两大邻国，边界漫长，双方吸取历史教训，建立了不结盟、不对抗、不针对第三方的睦邻友好关系，增进战略互信，建立全面战略伙伴关系，两国交往是正常的国与国交往。 能源合作：中国从俄罗斯购买油气是基于民众需求，短期内难以找到其他国家提供如此巨量且稳定的供应，反对将经贸问题政治化作为打压中国的工具。 中国在地区热点问题上的立场：历来主张通过对话寻求政治解决争端冲突，武力和制裁不能彻底解决问题。 在乌克兰问题上的具体主张：自2022年2月25日（危机爆发第二天）起，中方就提出对话协商解决。习近平主席提出四点主张：各国主权和领土完整应得到尊重，联合国宪章应得到遵守，各国合理安全关切应得到重视，一切致力于和平的努力都应得到支持。中方以此为遵循推进劝和促谈，派出特使斡旋，同巴西等南方国家发起“和平之友”。 中国立场的评价：公正、客观、理性、务实，体现国际社会最大共识。任何冲突的终点都是谈判桌。中方乐见一切致力于和平的努力，认为所有当事方及利益攸关方都应适时参与和谈进程。欧洲在解决危机根源、探讨长治久安、构建均衡有效可持续的欧洲安全框架方面应发挥重要作用。 关于中美关系的展望 中国对美政策：保持连续性和稳定性，体现大国战略定力和国际信誉。政策核心是习近平主席提出的三原则：相互尊重、和平共处、合作共赢。 相互尊重：中美制度不同是各自人民的选择，改造或颠覆对方不切实际，相互尊重是交往前提。 和平共处：中美两个大国不能冲突，否则殃及世界，应开展对话、加强交往、增进了解、建立信任。 合作共赢：国际社会期待中美合作，全球性挑战需要中美联手应对，这是两国应承担的国际责任。 中方态度：已准备好按三原则同美方构建稳定、健康、可持续的双边关系，找到正确相处之道。希望美方相向而行。若美方坚持打压遏制，中方将奉陪到底，坚定维护中国主权、尊严和正当发展权利，回击美方单极和霸凌行径，维护国际公平正义和国际关系基本准则。 中国的信念：中国人不信邪、不怕鬼，新中国在战胜艰难险阻中发展壮大。引用古语“天行健，君子自强不息”“他强任他强，清风拂山岗；他横任他横，明月照大江”“任尔东西南北风，我自岿然不动”表达应对挑战的决心。对世界前途和中美关系未来充满信心，中美共同努力方向是相互尊重、和平共处、合作共赢，这也是国际社会最大期待。 后续安排 中国代表将前往纽约参加安理会会议。 会议主持人希望中国代表能利用慕尼黑安全会议的机会，与美国新政府代表会面，推动更多对话和讨论。 内容由 AI ⽣成，仅供参考 | S2: 3 | T2: 3 | U2: 5 | W2: =(S2+T2+U2)/3 -> 3.6666667 | X2: 1.3：摘要中多处将'慕安会'误写为'安理会'（如'安理会报告主题'、'安理会近年来邀请'等），关键组织名称提取错误，影响准确性；1.3：摘要中'联合国成立时11个会员国'，原文为'51个会员国'，数字提取错误；2.3：摘要内容大量直接复述原文表述，如四点看法、对乌立场、对美关系等，缺少实质性提炼和概括，冗余内容超过50%，影响摘要的凝练性。
A3: 2 | B3: 段功宸 | C3: • 发言者 1 01:35 好的，同学们欢迎回来。我们刚刚说了一点小小的插曲，但是没有关系，我们在接下来的时间里面呢，把时间交给咱们的电子科学与工程学院的三位老师，来给大家介绍一下我们学院的一个整体的情况。好。 • 发言者 2 01:54 同学们家长们上午好。首先我给大家汇报一下电子学院的学院历史情况。在电子科技大学建校之初，1956年就成立了无线电系，电真空器件系无线电零件系，1979年1992年2001年2018年，经过4次的院系调整，成立了电子科学与工程学院，科普示范性微电子学院。2023年响应国家新的号召，成立了电子科学与工程学院与基层电路学院。电子科学与与技术是电子学院的一级学科，它属于国家重点一级学科。它下面有5个二级学科方向，第1个是电磁场与微波技术，第二是电路与系统，第三是微电子学与固体电子学，第四是物理电子学。 • 发言者 2 02:47 第五是电磁信息功能材料与机构。还有三个国防特色学科，分别是电磁场与微波军用关键材料。电子元器件，在党建方面，学校党委入选了教育部首批全国党建工作标杆院系学院，荣获全国教育系统先进集体。人才培养方面，本科生现有有1545人，招生专业是工科试验班，电子工程类有两个专业方向，第一是电子科学技术。国家特色专业，国家级一流本科专业建设点电磁场与无线技术。研究生方面，现有硕士和博士研究生1975人，招生专业学硕学位博士是电子科学与技术，硕士是电子科学与技术，材料科学与工程。 • 发言者 2 04:05 专业学位博士电子信息硕士电子信息材料工程。二等奖5项。本科生深造率稳中有进。创新创意竞赛屡创佳绩。研究生科研学术能力不断加强，就你布局不断优化，还有还涌现出了许多优秀的个人和集体。代表性的党建思政荣誉等。下面给大家介绍一下我院教职龚总体构成情况，现有教师302人，教研系第139人，科研系第95人。教学系第14人，实验系第21人，教师总数269人，机关33人。实施队伍情况，两院院士两人，领军人才19人，青年人才28人，其他类型人才12人，后继61人。 • 发言者 2 05:23 融合两个全国高校黄大年式教师团队，第1个是第2个是电磁辐射与散射。教师团队2022年融合4个国家自然科学基金为创新群体。科研方面，近5年科研金到账经费稳定在3~4亿元之间。项目构成以纵向项目为主，横向项目为辅。科研成果牵头获得国家国家科技奖励11项。近5年发表高水平学术论文2000余篇。专利申请1600余件，授权1300余件。科研团队一共有20个科研团队，年度经费过千亿元的团队15个，其中过亿元团队一个，科研方向。 • 发言者 2 06:35 材料器件电路系统形成了完整的这个削缩链条。从基础科学研究到工程实践，再到产业化，形成了一条龙的创新体系。拥有两个国家级平台，第一是国家电子辐射控制材料工程技术研究中心，第二是微波电子工器件国家级重点实验室。拥有4个国国际合作平台，7个省部级科研平台。在国际交流方面共建国际姊妹院系两个。香港大学电机工程电子系，香港城市大学电子工程系。主办高水平国际会议13场，学生长短期交流项目20多。20多个项目。 • 发言者 2 07:36 好。地聆听。 • 发言者 1 07:43 好的，非常感谢我们段院的介绍，那接下来我们有请下一位老师。好，感谢主持人。 • 发言者 3 07:50 那么下面有我的话给大家介绍一下电子信息材料与元器元器件这个方向。好，那么首先的话电子信息这个方向的话，它主要涉及的是电子材料与电子器件。那么这两个的话它在IT领域它这个地位的话是以物质基础与先导来推动后面这个电路系统与电子装备的这样一个研发，那么用于基于比较好的话来去概括它的话，就是一代材料催生一代器件。那么服务一代整机，那么这个方向的内涵的话，它是以电子在物质中的这样一个输运特性，那么这里面包括电磁声光热力，还有化学生物类比特性。 • 发言者 3 08:36 以及外部的这样一个作用为基础，来设计研究和生产电子器件。那么主要涉及到是电子材料器件电路它的设计研制生产和应用。那么它是以材料为基础，器件为核心，然后应用为目标导向。那我们知道中国的话可以说是一个电子产品的这样一个生产大国，但是的话目前来说还不敢说是一个强国。那么实际上我们在2021年的话，中国集成电路这个电子产品，它的进口额度的话就已经达到了2.8万元，那么这个数据的话大概是原有进口量的这个1. • 发言者 3 09:22 7倍。这个先进电子材料元器件电路系统等电子产品的话，它是我国目前最为紧迫的这样一个卡脖子的问题之一。好，那么电子产品的话实际上它也是我国的重大需求，那么它在6g通讯量子技术智慧城市光电技术新能源智能电子等领域的话都起着非常重要的作用重要的作用。那么同时电子产品的话也是我国这个国民经济的这个关键支撑，那么它已经广泛的应用在物联网移动设备和网络基础设施，无人驾驶航空航天医疗健康和穿戴可穿戴这样一个设备。 • 发言者 3 10:14 等领域。达到万亿美元这样一个量级。那么电子产品的话，它目前的话是向着小型化多功能低功耗智能化的方向在发展。那么举个例子的话，我们的手机的话它现在是越来越多的功功能在向里面去集成，那么这个就需要我们越来越多的这样一个电子元器件去集成到我们这样一个小的手机的这样一个里面去。好，那么这就要求我们的元器件朝着微型化片式化集成化薄膜化和智能化的方向去发展。那么尤其重要的是材料和器件一体化。那么集成技术总的这样一个发展趋势的话，是将摩尔定律它的这样一个制成的这样一个不断的这样缩小的这样一个方式和超摩尔定律这个功能不断的多样化的这样一个两个方式去结合起来。 • 发言者 3 11:02 那么通过那么具体的话可以通过借电铁电压电磁性还有半导体这些重要的功能材料，它通过结构符合与功能集成来实现这个信息的获取，同时信息的处理。那么这样的话就可以形成我们这样具有新一代星系技术物质形态，或者是半导体技术的物理载体的这样一个固态的电子薄膜，然后去推动我们整个领域的这样一个前沿的发展。和创新这个源头的不断的产生。那么我们这个方向的话，它的这个研究队伍的话是包括有国家级的人才10余人，方这个方向的这个研究这个研究团队的话主要包括两个，一个是我们的邓龙江院士所在的这样一个电磁辐射控制材料，与技术团队，那么团队现有研究人员19人，那么其中正高13。 • 发言者 3 12:26 副高15人，那么结构和器件的研究。那么近年来的话是发表了包括自然在内的这个论文有300余篇，然后也承担了国家省部级以及国际合作等研究课题。130余项，然后年金年均到账经费的话是3000多万元。然后授权发明专利是100余项，并获得了国家科技进步或者国际那个技术发明奖。二等奖共计三项。另一个团队的话是张怀武教授这个领导的磁电薄膜与微型器件团队。那么现有的话是研究人员是17人，其中包括正高15人，副高两人，那么重点开展Ltcc材料及集成技术，微波毫米波晶圆及器件，自旋电子与磁量子器件传感器芯片等研究。 • 发言者 3 13:31 那么也是承担了国家重点研发计划，自然基金重点重大科学仪器项目，还有国际合作等项目100余项，然后科技进步二等奖共计三项。那么发表SCI论文400余篇。年均到账经费是2000余万元。那么我们这个方向的话主要是依托的两个国家级的平台，然后第1个的话是国家电磁辐射控制材料工程技术研究中心。那么这个中心的话它的历史可以追溯到1990年这样一个校级的材料与技术研究中心，然后随后的话是经过了2008年以及2013年两次这样的一个这个升级，然后最后呢它形成了我们现在的这样一个国家级的研究中心平台。 • 发言者 3 14:26 然后主要开展的话是多频谱涂层，电磁材料与结构以及智能材料与结构的这样一个研究。这个国际一流的这样一个实验平台，同时的话也拥有例如成都嘉驰电子科技这样的很好的这个存货成果转化基地。另外一个国家集体平台的话是电磁薄膜与集成器件全国重点实验室。那么它是2006年依托这样一个新型传感器，功率半导体技术，电子信息材料，这样三个这个部级的这样一个重点实验室来筹建的。那么它是结合电子信息系统微小型化和单片集成的重大需求，然后围绕我们的电子薄膜材料和集成器件开展基础应用，基础工程应用这个方面的研究。 • 发言者 3 15:19 然后主要形成了三个重点方向是电子聚合物与阵列传感器以及功率半导体与集成技术。我们这个方向的话大也拥有很好的这样一个研究条件。那么科研这个面积的话就达到了2万余平米，然后其中超精尖的话有3000平。建设了两条国家重大任务试验生产线，那么拥有大型的这样一个设备或者系统的话是500余台套。那么构建了材料器件电路系统全链条的这样一个研究平台，实现了这样一个测试表征这样一个全覆盖。那么具体讲材料制备方面的话是拥有各类液相外延磁控溅射， • 发言者 3 16:06 化学气相沉积分数外延原子沉积等等这样一个薄膜材料的这个制备设备大概有50余台套。微细加工方面的话是拥有步进式光刻机生潮反应离子刻蚀机等为代表的这样一个先进的微纳加工设备30台套，然后具有的话对电子功能薄膜进行微图形化的加工能力，形成了较为完善的这样一个然后材料的结构分析方面的话是拥有X射线衍射仪粒度分析仪X射线光电子能谱仪扫描电镜扫描探针显微镜透射电镜等等这样一个材料，这个微观表征的这样一个设备大概10余台套。 • 发言者 3 16:57 材料器件的性能测试方面的话是拥有浪漫光谱分光度计差热分析仪傅立叶红外光谱等材料性能这个测试设备也有50余台套。我们方向的研究成果的话是也是非常的丰富和多样性的。那么其中高水平论文方面的话，我们是在自然科学以及它的子刊，那么近年呢近年来的话每年都有多篇的这样一个重要的文章发表。那么奖项方面的话，我们是已经获得了包括国家科技国家技术发明这样一个奖项，共计有7项。那么我们毕业生的去向的话也是也是遍布了这样一个产业界与学术界。 • 发言者 3 17:47 那么它们其中包括了英特尔中芯国际华为德州仪器，高校和科研院所，那么他们成为了这个领域的学术牛人，技术大拿创新创业能手，在前沿的基础研究，军工项目研发以及这个产品技术开发等方向的话，是做出了重要的贡献。那么举几个例子，那么我们在读的这个杨伟豪同学的话，他是在这个磁性的非汇率表面已经做出了很系统很很多的这样一个工作。那么他目前的话是已经以第一作者分别在自然电子自然通讯上各发表一篇学术论文。那么我们的5G滤波器芯片学生团队的话，也是获得了挑战杯创新创业大赛的四川省的金奖。那么黄飞的话是我们210212018年的四川省的优秀毕业生，那么他也是获得了这样一个后面的这个斯坦福攻读博士的这样一个全额奖学金。 • 发言者 3 18:43 李凤霞的话也是我们的这样一个早期的优秀毕业生的代表。他们读博期间呢就发表了这个学术论文16篇，其中一作的话是6篇，而严巍的话是我们去年刚刚毕业的这个优秀毕业生的代表，那么他20年的话就获得了华为光产线的这样一个优秀合作项目奖，然后去年的话更是获得了这样一个21届的王大珞光学奖，那么他博士毕业以后就有就以优秀青年学者的身份加入了这样一个苏州大学。好，万位的话是我们这样一个现在在产业界的这样一个优秀的学生代表， • 发言者 3 19:29 毕业生的代表，那么他目前是河北美泰电子科技公司的这样一个副总，那么他率先的话是带领团队采用names,工艺的话研制出了siw这样一个环形器隔离器，然后突破了这样一个卡博士器件的这样一个核心技术，实现了高性能的这样一个非护翼器件的产业化。那个报考这个电子信息材料与元器件方向。 • 发言者 1 20:04 好的，非常感谢我们柳教授的介绍，那接下来我们把时间给到我们的张教授，好。好， • 发言者 4 20:16 各位同学各位家长早上好，我将为大家来介绍电磁场与微波技术和电路与系统两个专业方向。那么我将逐步的涵盖我们的电磁场与微波技术学科以及电路与系统学科，包括两个学科共同取得的人才培养的一些成果情况。那么首先跟大家介绍一下我们这两个专业主要在做什么。关于电磁场与微波技术呢，电磁场与微波技术其实包含了4个细分的专业方向，包括微波毫米波电路电波传播与电磁兼容计算，电磁学与工程电子学天线理论与技术，它其实涵盖了整个的射频微波的整套的系统的所有的研发方向，而与之相与之相关的电路与系统专业呢包含了非线性电路与复杂电子系统，射频微波电路与系统以及集成电路与系统三个专业方向。 • 发言者 4 20:55 那么这电电磁场与微波技术和电子助理系统共同组建了我们整个的射频电电子系统的全方位的各个专业覆盖方向。那么首先呢我先为大家来介绍一下电磁场与微波技术学科的相关学科情况。电磁场与微波技术学科呢它的历史沿革是始于1956年，电子科技大学建校时期，由林卫干先生和谢楚芳先生两位共同创创建了这个电磁场与微波技术专业。在这个整个的历史发展过程中呢，形成了电磁场与无线技术国家特色级专业以及电波传播与天线国防紧缺特色专业，两个专业方向，在之后呢也所属的一级学科电子科学与技术学科也入选了双一流a类的学科。 • 发言者 4 21:58 在其他众多的中青年优秀教优秀师资研究方向涵盖了本学科的所有的主流方向。电子厂有一波技术，主要有6个团队组成，分别是电磁辐射与散射团队。毫米波技术与系统应用团队，微波毫米波集成电路与系统团队，电磁兼容技术团队。微波测量与成微波测试与成像技术团队以及无线技术与集成系统团队。在学科平台方面，整个专业方向包含了国家自然基金委创新群体。国家高等学校学科创科创学科创新引智基地，国家工程技术研究中心以及国家级重点实验室。 • 发言者 4 22:49 在硬件平台方面，学科拥有中国高校最为先进的微波暗室群体。以及先进的微波毫米波太Hz仿真测试平台。下下面我来介绍一下电磁场有一波技术学科方向的一些我们学院的一些主要的研究成果。在天线理论与基础方向呢，学院的杨世文教授团队研究了四维天线阵列技术，为天线阵列设计提供新的自由度，实现了低成本高性能。以及提升系统的整体性能。同样的杨世文教授团队也在强耦合超宽带相控阵方面取得了一系列的研究进展，相关的应用成果也应用于中电14所某大型机载相控阵雷达。 • 发言者 4 23:36 樊勇教授团队呢研究了毫米波平面集成天线集成天线，该成果可以广泛的应用于毫米波通信雷达系统领域。丰富的研究基础。在电磁电波传播与电磁兼容方向呢，李恩教授团队所引领的这个微波毫米波测量技术也突破了众多的技术封锁，有着60多年的技术积累和传承。杨世文教授团队呢在电磁测井仪器方面也取得了一些研究，获得了国家科技进步二等奖一项，也相关的成果也在中海油成功的推广应用。延波在微波毫米波电路方向呢，延波教授团队引领的这个微波毫米波太Hz芯片的研究，取得了一系列的相应的成果，也收获了这个国家科技重大专项以及军科委的相关的这种应用于新一代的高速通信系统。 • 发言者 4 24:40 延波教授团队呢还在微波毫米波器件与系统方面取得了一系列的固态合成功率源天线阵列扩电网络等电路与通信雷达系统。延波教授团队还在微波毫毫米波微系统技术方面取得了一系列的进展，其中包含三毫米的三毫米的导引头前端，毫米波毫毫米波的引信前端以及8毫米的宽带的收发前端。在计算电磁学与工程电磁学方面，杨世文教授团队所引领的这个计算电磁学研究方向是取得了一系列的重要的成果，其中的相关的算法呢也是被评为20世纪十大算法之一。同样的樊勇教授团队呢在太Hz雷达成像方面也取得了一些一系列进展，成功研制出了0. • 发言者 4 25:30 22太Hz0.34太Hz0.42太Hz的雷达成像系统，实验平台分辨率小于一个厘米。樊勇教授团教授团队同时还在太Hz通信技术方面有一些的突破进展，那么我们的成果在2023年的成都大运会田径项目中成功的示范应用。同时呢李恩教授团队在电磁波与物质互作用机理及测评系统方面，面向5G通信高性能系统生物医学新能源等方向提供了充足的应用需求和相关的研究成果。同时呢李恩教授团队呢还在生物医学电磁学及成像方向取得了一些进展，前期成果发表了大量的高水平论文，以及有20余项的这个国家发明专利。 • 发言者 4 26:28 下面呢我再来为大家介绍一下电路与系统学科的相关相关方向。81年开始招收研究生，同时也招收这个博士研究生，88年成立了首批博士后流动医院。学科呢包含了教育部国际合作联合实验室，以及国家高等学校学科创新引智基地，拥有国家级人才4人，新世纪人才两人。教授10人，副教授22人，包含了非非线性电路与复杂电子系统，射频微波电路与系统集成电路与系统三个研究方向。下面我来介绍一下我们的主要的一些研究方向与研研究成果。 • 发言者 4 27:19 在集成物理研究方向呢由樊勇教授和王成教授团所组成的团队，樊勇教授和李廷军教授团队呢在高速车地通信系统方面取得了一系列的进展，主要从事高速磁浮交通的38gHz车地通信系统的研制。是一种高效经济和安全的交通技术。那么通过这种技术呢可以实现安全可靠实时宽带等的等的这个研究技术，可以确保列车的安全运行和基本保障。樊勇教授团队和张静直也就是我本人的研究团队呢，主要是工作在毫米波通信雷达CMOS芯片面向通讯雷达领领域的新应用新场景新应用，探索集成电路设计的新架构。 • 发言者 4 28:26 他康凯教授团队呢在毫米波CMOS芯片方向呢取得了一系列的研究成果和进展，包括了这个超宽带的模块级芯片以及5G通信系统和这种雷达系统的研制。最后呢我来为大家介绍一下这两个专业方向的人才培养情况。在人才培养方面呢，我们连续三年获得全国大学生集成电路创新创业大赛奖项，荣获华为优秀合作项目奖，荣获这个研究生优秀导学团队提名奖。学生成才我们以因材施我我们因材施教，科学育人，宗旨是在育才先育德师生共师生齐共建方面。 • 发言者 4 29:10 常态化的开展学术组会，我们在学生培养方面取得了大量的荣誉，包括这个互联网加的奖项，包括这个国际上HPV的各种各样的奖项，以及我们相关的优秀论文以及创新创业大赛的取得的各种成果的奖项。在就业方面呢我们的就业领域分布广泛，包括行业的领军企业，如华为中兴等以及各大的研究所高校，以及也我们的毕业生也在海外留学上方面也取得了不不少的突破。那么以上就是我的全部介绍，那么电子科技大学电子工程学院欢迎你们的加入，谢谢。 • 发言者 1 30:02 好的，非常感谢我们张教授的介绍，那刚刚我们当院给大家介绍了学院的一个整体的情况，我们的剩下的两位老师呢给大家介绍了，我们可能代表着不同的这样的一个研究的方向，那同学们我们稍作休息，那如果有什么问题我们也非常欢迎大家在弹幕区里面问出来，稍后我们还有其他的老师和同学给大家做分享，结束之后呢我们会抽可能比较有代表的几个问题来给同学们做解答。好，同学们稍作休息，稍后待会见。好的，同学们欢迎回来。现在坐在段院旁边的是我们的博士生导师李天明教授，各位同学， • 发言者 5 32:49 各位家长上午好。 • 发言者 1 32:50 在我们李教授旁边是非常优秀的学生代表，也是我们的在读博士田雨彤彤同学。各位同学各位家长 • 发言者 6 32:58 大家上午好， • 发言者 1 32:59 欢迎两位先来到我们的直播间做客，那我们接下来把时间就交给我们的老师和同学吧。行， • 发言者 5 33:06 各位同学各位家长大家上午好，我是来自电子学院的李天明。下面我来介绍这个物理电子学这个学科方向。我的介绍呢分为两个部分，第一呢是物理电子学的学科定义及其范畴。第二呢是我们学校的的物理电子学。首先呢我要介介绍一下物理电子学的学科定义及其范畴，物理电子学呢从名字上来看，他就知道它是物理学跟电子科学技术的一个交叉的一个学科。它物理学学是研究物质能量的本质与性质的，自然科学电子科学与技术呢它是研究电子在不同电子中的运动规律和与物质的相互作用， • 发言者 5 33:34 利用这种作用呢研制的一系列的电子器件，那么它们两个结合起来呢，它是将物理学的最新的研究成果应用在我们的电子学中，从而产生一些新的这个电子器件。那么在这里面比较典型的就是微波跟电子的相互作用，那么我们就称为微波电子学，就产生了一系列的微波电真空器件，我们的光与电子相互作用，那么我们就产生一系列的就形成了光电子学，形成了一系列的光电器件。我觉得是有几大几个方面，第一呢它内容是不断充实的，像比如说现在的量子技术发展非常快，现在的量子电子学的内容呢唉它逐渐在在增加。 • 发言者 5 34:42 第2个呢它的学科边界呢它不一定非常清晰，它归类不一定就非常的完整。比如说光电子学它既可以算是我们物理电子学方向的一个内容，它也可以属于另外一个学科光学工程的一级学科。这个学科的特特点呢我觉得有以下几个方面，第1个呢它是基础性与前沿性，我们的物理学它比较强调基础，它的数理基础要求好，然后呢他把物理的最新的研究成果呢应用在我们的电子学上，所以它有一个应用的前沿性。那么在物理电子学它所生成的一系列的电子器件呢， • 发言者 5 35:15 它是我们信息科技产业中它的非常重要，所以说我们的物理电子学呢是支撑现代信息技术的一个关键的一个技术学科。第2部分呢就是我们学校的物理电子学，其实每个学校它的这个半物理电子学这个方向的学校很多，但是每个学校它的侧重点不一样，比如说东南大学它的侧重点呢就可能是这个微波电控器件这一类电子器件，微波电控器件它是产生微波的这样子一个器件。这个器件这个微波在这个频谱上它具有非常广泛的应用。大家可以看这个频率的分配表， • 发言者 5 35:54 在这个微波这个阶段呢它通信雷达它的微波的应用它都非常的广泛，那么这这些里面有一个典型的器件，就是我们传统的微波电子学所研究的内容，我们学校的传统的强项，比如说是回旋管的，研究它的行波管的研究磁控管的研究这些器件都是是的，我们都已经那么我们学校的物理电子学呢它的起源于我们的电磁工专业，在一建校的时候，1956年建校的时候，在俄罗斯专家的就是前苏联专家的这个帮助下，我们成立了这个电子控。器件专业，当时这个专业呢归宿到我们的电子器件系。 • 发言者 5 36:49 在79年那时候呢在刘成刚院士带领下来，我们又成立了高能电子学研究所，这个专业得到了高能电子学研究所。01年的时候呢，当时的物理系应用所高能所呢就成成立了一个物理电子学在2018年的时候呢，在物理电子学院和电工学院和微工学院的部分呢，就成立了现在的电子科学与工程学院，所以说我们现在属于这个电子工学院的这个方向，电工学院的一个下面的一个专业。那么经过近70年的这种发展，我们学校的这个物理电子学它的内涵呢也在不断的扩展，它这个扩展呢分为两个方面，一个是它纵向的发发展，它往上游发展往下游发展，它上游呢就是仿真设计数字。 • 发言者 5 37:37 模拟材料它的下游呢是系统的应用系统应用。具有自主知识产权的商用软件，一个是mm st,另外一个呢是切皮克是国内的在广泛的应用的两款算法，这个商用软件。另外呢我们把现在的人工智能这个方向来引入到我们的这个器件设计和电子学的应用中，我们把这块人工智能的方向呢也引到我们的设计中去。然后在系统的应用方面呢，我们利用我们联知的这种功率的器件，我们研究了这得研制了毫米波的雷达，我们用回旋行波管做的。另外呢我们用这个行波管做了无线输能系统，因为我们用磁控管做的这个微波能的这个系统微波能干燥系统，这是它的系统应用的一个方向。 • 发言者 5 38:32 另外呢我称之为一个横向发展，它从微波它频段往上移到毫米波到钛合资这样子的一个方向。第2个呢就是我们跟其他学科的再深入的交叉，它跟医学的交叉。在钛资技术方面呢，我们引用了这个钛资的它的这种分辨率高，透视效果好的这种成果来做钛资成像，然后利用光跟电的相互结合来我们用光电融合的新的这种钛资源的这种方式。然后呢利用钛资这种宽频带的特点，我们把钛合资技术用到我们的通信里面去，做保密通信，做高速通讯进行应用，这是我们新的拓展方向。 • 发言者 5 39:10 在医学这块呢我们主要是利用钛合资成像应用到医学中的诊断，它提高我们诊断的准确性。重点实验室，有三个这个四川省的工程中心或者重点实验室，有一系列的行业的协会参与的，我们参与成立的。然后我们在这方面的成果也非常的显著，我们有一系列的国家奖省奖，我们每年到校的科研经费呢接近两个亿，在整个在我们学院里面呢也算是多的应该是最多的。在国际上呢我们现在是国际世界上最大的真空器件的研究中心，也算是世界上这个在国际上呢是小有名气，这几年名气是越来越大。 • 发言者 5 40:11 在2023年呢我们刚刚成功举办了这个行业内的这个顶级那么我们的团队呢在物理电子学方向的团队一共有9个，这个里面团队仔细介绍呢大家可以去看我们学院的网页，它现在呢更为详细。另外呢就是我们这个方向的学生的出口情况，这个学校的学院的这个车我数据我不掌握，但是我团团队的呢我们大概可以说一下，我们团队的学生基本上是1/3的硕博连读，1/3的呢去企业，1/3的呢去研究所，或其他呢就是去指那些公务员哪这一部分。 • 发言者 5 41:02 我自己个人呢他的每年有基本上两个学生研究生毕业，一个博士毕业，近三年呢两个学生今年去了 • 发言者 7 41:27 好，谢谢大家，物理电子学，欢迎大家。 • 发言者 5 41:32 好的， • 发言者 1 41:32 那接下来我们有请同学来给大家做一个分享。好， • 发言者 6 41:38 各位同学各位家长大家上午好，我是电子学院2023级电子科学与技术专业的博士研究生田雨桐。那么接下来呢我将从学生视角从结合我的个人感受，向大家介绍我选择电子学院的8个理由，并分享一些我个人开展研究生择校和专业选择的建议与经历。攻读研究生是学生生涯的又一重要里程碑，对于个人今后的学习工作生活有着深刻的指导意义。选择一个学校，选择一个专业，对今后的人生发展有着重要的导向作用。于我而言，在我的能力范围之内，能够选择一个位置突出，行业火热，实力强劲的学校和专业，对我今后的就业学习和生活都会有着重大影响。 • 发言者 6 42:23 那我所考虑的第1个成因素呢就是城市电子科技大学吸引我的一大方面是其所在的城市，成都是四川省会国家中心城市新一线城市。是国家历史文化名城，古蜀文明发祥地，中国十大古都之一。那么作为一个外地人呢，成都给我的最大一个印象就是城市宣传标广告标语叫做成都都城。重点指的是梦想都城。那么这句标语的底气来源于成都整座城市的古老文化底蕴与年轻经科技活力。那么古老文化底蕴我们已经知道了，年轻科技活力则与我们的产业相关。 • 发言者 6 43:05 电子信息是前景广阔且年轻的朝阳行业，而成都则是站在了国内电子信息这一朝阳产业发展的前端。从英特尔华为到京东方，新众多行业巨头汇聚于此，正提供了得天独厚的实践平台和就业资源。路过沙河老校区的建设路，能够看到国营电子厂的红砖厂房。那么如今在高新区高新区高新西区的清水河畔，那么京东方的柔性屏生产线以及华为研究所的玻璃幕墙鳞次栉比，如果你想在读书期间就接触真实的产业场景，成都会给你惊喜。那为什么选择电子科大？ • 发言者 6 43:55 因为它是我国电子信息人才培育的代名词。那么入学前呢我对学校印象最深的一句网络评价就是在这里走在路上都能捡到电阻等元器件。入学后发现这句话毫不夸张，学校里有电子信息博物馆，记录着我国第1台晶体管收音机的诞生。从电子科学技与技术信息与通信工程到集成电路科学与技术，学院构建了最完整的电子信息学科群，那么作为中国民族电子工业人才的摇篮，这里走出了大批行业领军者与顶尖学者同行，为同学们在电子信息前沿领域探索无限可能的机会。那么为什么选择电子科学与技术这个专业？ • 发言者 6 44:43 围绕这个专业而言，电子学院拥有全国第一的底气与担当，学院电子科学与技术学科在第4轮学科评估当中斩获a加稳居全国第一，从电磁场与微波技术到微电子与固体电子学，五大国防特色学科整构建了深厚的学科研底蕴。这个学科底蕴与我们学生最为相关的就是教师团队能够给予我们的能力提升帮扶与保障。学院研究团队的强大实力能够成为学生肆意发展的坚强后盾。具体到研究团队则是与我们的兴趣专业意向导师和研究方向有关系。那么这里和大家分享一下，我在入学前选择团队与导师的理由一家之言供大家参考。 • 发言者 6 45:29 我在选择导师时，在研究方向契合的基础上，期望能够找到一个志同道合的牛师益友。我所在的毫米波技术与系统应用团队，在团队负责人樊勇老师的带领下，围绕微波毫米波理论与技术天线理论与技术，元气元器件与电路通信技术与系统，还有雷达成像技术与系统五大稳定的研究方向开展研究，取得了一系列优秀的科研成果。那么在这个团队呢，我们的研究方向覆盖电磁场与微波技术，电路与系统能够学到从芯片封装天线电路模块到系统的全面知识。 • 发言者 6 46:11 以我从事的毫米波雷达通信信号处理研究为例，我可以根据自我自己的兴趣和创新想法做一个雷达或者无线通信系统。开展联合培养等。也正是基于这个条件，我们团队的许多同学和师兄师姐获得了全面培养，变得更加优秀，发表了大量的论文，在各大学术会议竞赛上取得佳绩，并且取得了一系列傲人的奖项。也正是如此，我们的同学们获得充分的训练，已进入知名企业和顶尖科研机构工作。以我们团队为例，团队的硕博毕业生能够实现百分百的就业率。 • 发言者 6 47:02 就业单位有各类民营企业，大型央国企和头部科研院所，东湖边的钢琴小屋，单独弹两首曲子。最难的最对我来说最难忘的是2021年的跨年，学校在主楼前的无人机灯光秀，用300架无人机拼出了电子科大英文简称uestc的字样，给了我给了初入学校的我留下了浪漫与科技交织的印象。最后就是同学们比较关心的奖助体系学院构建了全覆盖高额度长周期的奖助体系。奖学金方面有国家奖学金学业奖学金专项奖学金新生奖学金以还还有学校和学院设立的其他奖学金以及奖助方面的校园地，国家助学贷款和生源地。 • 发言者 6 48:01 和生源地的直营助学贷款，那么讲完了学校层学院层面的选择理由，接下来想跟大家分享一下来到电子学院之前的二三事。对于一名研究生新生而言，最重要的莫过于选择自己合适的导师了，大家可以根据自己的研究方向，先选择合适的研究团队，再选择合适的研究生导师。我们学院拥有四大学科和19个科研团体，大家可以从学院网站上按照自己的兴趣选择团队，再进入团队网页，找到合适导师。有时候导师的信息不太完整，如果有意向比较强烈的导师， • 发言者 6 48:35 但是还想进一步了解他的研究方向，大家可以借助我们学科常用的文献检索网站，如hbo E和中国知网，在相关网站上检索对应网络导师的论文情况和指导研究生毕业的情况。结结合兴趣广泛调研，了解导师具体研究，选择最合适自己的研究方向。提前沟通交流，近距离了解我们在学校的日常生活。期待未来与大家共赴求实求真大气大为的沉淀之约，在电子信息的星辰大海中扬帆起航，我的汇报就到这里，谢谢。 • 发言者 1 49:28 好的，非常感谢我们同学的精彩分享，那刚刚通过我们老师和同学的分享，相信大家对我们学院也有了一个更加具体的了解了。那接下来也有一些问题想要咨询到我们的老师和同学们。首先第1个还是也有很多朋友们在问到说我们这个夏令营的这样的一件事情，想问一下段院这边我们夏令营有没有具体的时间形式？ • 发言者 2 49:51 好的哥。好的，主持人。那各位同学各位家长，我们电子学院呢要计划就是今年会计划这个夏令营活动时间还待定，希望呢同学们感兴趣的话呢加入我们这个QQ群相关的信息呢，我们会唉到时会及时的发布，大概就回答到这儿，谢谢。 • 发言者 1 50:14 好，那同学们也可以去扫码加入我们的这个QQ群，那还是给大家念一下我们的QQ群号吧，大家也可以现在就加进去。 • 发言者 2 50:25 我念一下978499108。 • 发言者 1 50:32 978499108，同学们可以添加我们学院的QQ群进行详细的咨询和了解。好，那我们本场直播到这里也要接近尾声了，还是想有请段月给大家分享一下，或者说我们三位一起吧，我们来给大家分享一下我们本场的抽奖口令，奖品就是我们学校这样的一整套的马克杯。 • 发言者 2 50:53 好，我们的口口令口号是一生一世，做梦，未来。 • 发言者 1 51:00 那E是我们那个字母的E,一生一世，然后逐梦未来。 • 发言者 2 51:04 那同学们把这句 • 发言者 1 51:05 话打在我们的那个弹幕区里面，然后呢我们跟老师和同学一起倒数三个数，我们就截取屏幕被截到的同学们就是我们本场直播。的幸运的小同学们了。那我们还是再给大家展示一下这个还是比较精美的这样一整套，还有也比较有我们学院的学校的这样的一个特色，上面有一个咱们的这个电子科技大学的一个logo,还有配套的勺子和杯盖。那我们一起倒数吧，就跟老师一起好的来。321。让我们来看一下是哪些幸运的小同学。那大家还是比较积极的。 • 发言者 1 52:00 恭喜我们的发现大家取的名字都特别别扭吃，也和我们成都的这样的一个美食特色，然后我们的这个小提琴同学，还有我们的小镇里的人，以及唉4830同学应该已经念过了，然后还有我们的这个魏军老同学来恭喜我们的以上同学，就是咱们本场直播的幸运的小同学了，那大家可以去私信后台留下您的联系方式和我们的这个收货地址，我们的礼物可能在不久的将来就会派送到大家的家门口。好，那我们本场直播到这里就结束了，非常感谢镜头面前考生和家长朋友们的关注，也辛苦今天我们一共有5位好嘉宾来到我们的直播间和大家做分享，我们也非常期待能够在或许在夏令营或许在我们到时候研究生入学的时候，和大家来一场面对面的沟通和交流。 • 发言者 1 53:01 好，同学们后会有期了，再见。 • 发言者 2 53:06 好再见。 | D3: # 沟通背景与目的 本次交流会由电子科技大学电子科学与工程学院组织，旨在向潜在考生和家长详细介绍学院整体情况、各学科方向特色及人才培养成果。通过多位学院领导和教师的讲解，以及在读博士生的分享，全面展示学院在电子科学与技术领域的学科优势、科研实力、人才培养体系和就业前景。 # 信息同步 ## 学院整体情况 - 电子科学与工程学院由无线电系、电真空器件系、无线电零件系等发展而来，经过1979年、1992年、2001年、2018年四次院系调整成立 - 电子科学与技术为国家重点一级学科，包含5个二级学科方向：电磁场与微波技术、电路与系统、微电子学与固体电子学、物理电子学、电磁信息功能材料与机构 - 拥有3个国防特色学科：电磁场与微波军用关键材料、电子元器件 - 学院党委入选教育部首批全国党建工作标杆院系，荣获全国教育系统先进集体 - 本科生现有1545人，招生专业为工科试验班，电子工程类包含电子科学与技术（国家特色专业，国家级一流本科专业建设点）、电磁场与无线技术 - 研究生现有1975人，招生专业包括电子科学与技术（学硕、博士）、材料科学与工程（硕士）、专业学位博士电子信息、硕士电子信息、材料工程 - 教师队伍共302人，其中教学系139人，科研系95人，实验系21人，机关33人 - 两院院士2人，领军人才19人，青年人才28人，其他类型人才12人 - 拥有2个全国高校黄大年式教师团队：电磁辐射与散射团队 ## 科研实力 - 近5年科研经费到账稳定在3-4亿元之间 - 牵头获得国家科技奖励11项 - 近5年发表高水平学术论文2000余篇 - 专利申请1600余件，授权1300余件 - 拥有2个国家级平台：国家电子辐射控制材料工程技术研究中心、微波电子工器件国家级重点实验室 - 拥有4个国际合作平台和7个省部级科研平台 - 建有中国高校最先进的微波暗室群体和先进的微波毫米波太赫兹仿真测试平台 ## 电子信息材料与元器件方向 - 中国是电子产品生产大国但不是强国，2021年集成电路进口额度达2.8万亿元，是原有进口量的1.7倍 - 电子产品在6G通讯、量子技术、智慧城市、光电技术、新能源、智能电子等领域起重要作用 - 电子产品发展方向：小型化、多功能、低功耗、智能化 - 研究队伍包括国家级人才10余人 - 两个主要研究团队： - 邓龙江院士团队（电磁辐射控制材料与技术团队）：研究人员19人，正高13人，副高15人，发表论文300余篇，承担课题130余项，年均到账经费3000多万元 - 张怀武教授团队（磁电薄膜与微型器件团队）：研究人员17人，正高15人，副高2人，承担课题100余项，年均到账经费2000余万元 - 依托两个国家级平台：国家电磁辐射控制材料工程技术研究中心、电磁薄膜与集成器件全国重点实验室 - 科研条件： - 科研面积2万余平米，其中超精尖3000平米 - 建设了两条国家重大任务试验生产线 - 拥有大型设备或系统500余台套 - 材料制备设备50余台套（包括液相外延磁控溅射、化学气相沉积、分子束外延、原子沉积等） - 微细加工设备30台套（包括步进式光刻机、反应离子刻蚀机等） - 材料结构分析设备10余台套（包括X射线衍射仪、粒度分析仪、X射线光电子能谱仪、扫描电镜、扫描探针显微镜、透射电镜等） - 材料器件性能测试设备50余台套（包括光谱分光度计、差热分析仪、傅立叶红外光谱等） ## 物理电子学方向 - 学科起源可追溯至1956年建校时期，由前苏联专家帮助建立的电子管器件专业 - 1979年在刘成刚院士带领下成立高能电子学研究所 - 2001年物理系应用所、高能所成立物理电子学 - 2018年整合物理电子学院和电工学院部分成立现在的电子科学与工程学院 - 学科特点： - 基础性与前沿性结合 - 学科边界不清晰，存在交叉 - 纵向发展：从仿真设计、数字模拟材料到系统应用 - 横向发展：从微波频段向毫米波、太赫兹频段拓展 - 研究成果： - 拥有mmst、切皮克等具有自主知识产权的商用软件 - 将人工智能引入器件设计和电子学应用 - 研制了毫米波雷达、无线输能系统、微波能干燥系统 - 在太赫兹技术方面，利用其高分辨率和透视效果进行成像 - 将太赫兹技术应用于通信领域，实现保密通信和高速通信 - 在医学领域，利用太赫兹成像提高诊断准确性 - 拥有3个四川省工程中心或重点实验室 - 每年到校科研经费接近2亿元 - 国际上是世界上最大的真空器件研究中心之一 - 2023年成功举办了行业顶级会议 - 学生出口情况： - 约1/3硕博连读 - 约1/3进入企业 - 约1/3进入研究所或公务员系统 ## 人才培养 - 本科生深造率稳中有进 - 创新创意竞赛屡创佳绩 - 研究生科研学术能力不断加强 - 学院连续三年获得全国大学生集成电路创新创业大赛奖项 - 荣获华为优秀合作项目奖 - 荣获研究生优秀导学团队提名奖 - 学生培养成果包括： - 互联网+奖项 - 国际HPV各类奖项 - 优秀论文奖项 - 创新创业大赛成果奖项 ## 在读博士生分享 - 电子科技大学吸引人的城市因素：成都作为国家历史文化名城和新一线城市，电子信息产业发达 - 电子科技大学的学科优势：拥有最完整的电子信息学科群，第四轮学科评估中电子科学与技术学科获得A+ - 选择研究团队与导师的建议： - 根据研究方向选择合适的团队 - 通过学院网站了解团队和导师信息 - 利用文献检索网站（如HBO E、中国知网）了解导师的论文和指导研究生情况 - 毫米波技术与系统应用团队： - 围绕微波毫米波理论与技术、天线理论与技术、元器件与电路、通信技术与系统、雷达成像技术与系统五大方向 - 覆盖电磁场与微波技术、电路与系统两个专业 - 学生可获得全面培养，发表大量论文，获得各类奖项 - 毕业生就业率100%，就业单位包括各类民营企业、大型央国企和头部科研院所 - 奖助体系： - 奖学金包括国家奖学金、学业奖学金、专项奖学金、新生奖学金等 - 助学体系包括校园地国家助学贷款和生源地助学贷款 # 达成共识 - 电子科学与工程学院计划举办夏令营活动，具体时间待定 - 学院QQ群号为978499108，用于发布相关信息 - 本场直播的抽奖口令为"一生一世，逐梦未来" - > "一生一世，逐梦未来" # 待协调事项 无 | E3: 5 | F3: 4 | G3: 3 | H3: 0 | I3: =(E3+F3+G3)/3 -> 4 | J3: 2.1 核心遗漏：没有提及具体的建院时间 3.2 小标题合理性：信息同步这个小标题过于宽泛，达成共识标题不合理 3.4 内容重复多次：抽奖口令提到了两次 | K3: 本次学院介绍活动围绕电子科学与工程学院的整体情况及重点研究方向展开，涵盖了学科建设、师资队伍、科研成果、人才培养及招生政策等内容，全面展示了学院在电子信息领域的实力与特色。 学院概况与历史沿革 建制与发展历程 学院前身为1956年建校时设立的无线电系、电真空器件系、无线电零件系，历经1979年、1992年、2001年、2018年四次院系调整，于2018年成立电子科学与工程学院（示范性微电子学院）。 2023年响应国家号召，进一步整合资源，成立电子科学与工程学院与基层电力学院。 学科地位 电子科学与技术为国家重点一级学科，在第四轮学科评估中获评A+，位列全国第一。 拥有五个二级学科方向：电磁场与微波技术、电路与系统、微电子学与固体电子学、物理电子学、电子信息功能材料与机构。 三个国防特色学科：电磁场与微波、军用关键材料、电子元器件。 师资与组织架构 教职工构成 现有教师总数302人，其中教研系列139人、科研系列95人、教学系列14人、实验系列21人，机关人员33人。 师资队伍中含两院院士2人、领军人才19人、青年人才28人、其他类型人才12人，合计61人。 国家级教学团队 太赫兹科学技术研究中心教师团队（2018年入选） 电磁辐射与散射教师团队（2022年入选） 荣获四个国家自然科学基金委创新群体。 人才培养体系 本科生培养 在校本科生1545人，招生专业为工科试验班、电子工程类。 包含两个专业方向：电子科学技术国家特色专业、国家级一流本科专业建设点，以及电子厂与无线技术方向。 本科生深造率稳中有升，创新创业竞赛成绩突出。 研究生培养 在校硕士与博士研究生共1975人。 学术学位招生专业为电子科学与技术（硕博）、材料科学与工程（硕士）；专业学位为电子信息、材料工程。 荣获国家级教学成果奖二等奖5项。 研究生科研能力持续提升，就业布局不断优化。 科研实力与平台建设 科研经费与成果 近五年科研到账经费稳定在3~4亿元之间，以纵向项目为主、横向项目为辅。 牵头获得国家科技奖励11项，发表高水平学术论文2000余篇，申请专利1600余件，授权1300余件。 拥有20个科研团队，其中年度经费超千万元的团队15个，过亿元团队1个。 国家级科研平台 国家电子辐射控制材料工程技术研究中心 微波电真空器件国家级重点实验室（即“电磁薄膜与集成器件全国重点实验室”） 其他平台 四个国际合作平台、七个省部级科研平台。 研究方向介绍：电子信息材料与元器件 战略意义与产业背景 电子信息材料与元器件是推动电路系统与整机发展的物质基础与先导领域，遵循“一代材料催生一代器件，服务一代整机”的发展逻辑。 2021年中国集成电路进口额达2.8万亿元，约为原油进口额的1.7倍，凸显其作为“卡脖子”问题的紧迫性。 广泛应用于6G通信、量子技术、智慧城市、新能源、智能穿戴等领域，预计2025年市场规模将达万亿美元量级。 发展趋势 向小型化、多功能、低功耗、智能化方向发展，要求元器件微型化、片式化、集成化、薄膜化、智能化。 发展路径结合摩尔定律（尺寸缩小）与超摩尔定律（功能多样化），通过三维集成微系统实现高附加值整合。 核心研究团队 邓龙江院士团队（电磁辐射控制材料与技术） 研究人员19人（正高13人，副高5人） 聚焦可见光、红外、微波等频段电磁辐射控制材料与器件 近年发表含《自然》在内论文300余篇，承担国家级及国际合作项目130余项，年均到账经费3000余万元，授权发明专利100余项，获国家科技进步或技术发明二等奖3项。 张怀武教授团队（LTCC薄膜微型器件） 研究人员17人（正高15人，副高2人） 研究方向包括LTCC材料与集成技术、微波毫米波晶圆器件、自旋电子与磁量子器件、传感器芯片 承担国家重点研发计划等项目100余项，发表SCI论文400余篇，年均到账经费2000万元，获国家技术发明或科技进步二等奖3项。 支撑平台与条件 依托两大国家级平台：国家电子辐射控制材料工程技术研究中心、电磁薄膜与集成器件全国重点实验室。 科研面积超20000平方米，含3000平方米超净间，建有两条国家重大任务实验生产线。 配备大型设备500余台套，覆盖材料制备、微细加工、结构分析与性能测试全链条。 材料制备：液相外延、磁控溅射、化学气相沉积、原子层沉积等设备50余台 微纳加工：光刻机、深槽反应离子刻蚀等先进设备30台套，具备亚微米级图形化能力 表征设备：XRD、XPS、SEM、TEM、AFM等十余台 性能测试：拉曼光谱、阻抗分析仪、分光光度计、DSC、FTIR等50余台 代表性成果与学生发展 近年在《自然·电子》《自然·通讯》等期刊持续发表高水平论文。 共获国家科技奖励7项。 毕业生广泛就职于英特尔、中芯国际、华为、德州仪器、中国电科等世界500强企业及国内外高校科研院所。 优秀案例： 杨伟豪：以第一作者在《自然·电子》《自然·通讯》各发表论文1篇 5G滤波器芯片学生团队：获“挑战杯”四川省金奖 黄飞（2018届）：获斯坦福大学全额奖学金攻读博士 李凤霞：博士期间发表论文16篇（一作6篇） 闫威：获华为光产线优秀合作项目奖、王大珩光学奖，博士毕业后加入数字大学 汪卫：河北美泰电子科技公司副总，带领团队突破MEMS工艺SIW环形器/隔离器核心技术，实现产业化 研究方向介绍：电磁场与微波技术 & 电路与系统 学科基础与师资力量 电磁场与微波技术始于1956年建校时期，由林维干、谢楚芳创建，拥有电子场与无线技术国家特色专业、电波传播与天线国防紧缺特色专业。 所属一级学科电子科学与技术为“双一流”A类学科。 师资涵盖国家级人才计划入选者19人，主要研究团队6个： 电磁辐射与散射团队 毫米波技术与系统应用团队 微波毫米波集成电路与系统团队 电磁兼容技术团队 微波测试与成像技术团队 无线技术与集成系统团队 科研平台 拥有国家自然科学基金委创新群体、高等学校学科创新引智基地、国家工程技术研究中心、国家级重点实验室。 配备中国高校最先进的微波暗室群及微波毫米波泰克斯仿真测试平台。 代表性研究成果 天线理论与技术 杨世文团队：提出四维天线阵列技术，提升系统性能；在强耦合超宽带相控阵方面取得进展，成果应用于中电十四所大型机载雷达。 毫米波平面集成天线 樊勇团队：为新一代毫米波前端平面化集成奠定基础。 微波测量与电磁兼容 李岩团队：积累60余年技术，突破多项封锁。 杨世文团队：电磁测井仪器研究获国家科技进步二等奖，并在中海油推广应用。 微波毫米波电路与系统 研波团队：开展泰克斯芯片研究，服务于高速通信系统重大专项。 演播团队：在大功率合成功放、固态功率源、天线阵列等领域取得突破。 闫波团队：研制三毫米导引头前端、八毫米宽带收发前端等毫米波微系统。 计算电磁学与工程电磁学 杨世文团队：相关算法被评为“二十世纪十大算法之一”。 樊勇团队：研制0.22THz、0.34THz、0.42THz雷达成像系统，分辨率<1cm，并在2023年成都大运会田径项目中示范应用。 李恩团队：在电磁波与物质互作用机理、生物医学电磁成像等方面发表大量高水平论文，获国家发明专利20余项。 电路与系统学科 国内首批硕士、博士学位授予单位（1981年起），1988年设立首批博士后流动站。 拥有教育部国际合作联合实验室、高等学校学科创新引智基地。 师资含国家级人才4人、新世纪人才2人、教授10人、副教授22人。 三大研究方向：非线性电路与复杂电子系统、射频微波电路与系统、集成电路与系统。 代表性研究成果 CMOS集成电路物理 韩勇、王成团队：聚焦CMOS芯片设计，研制分子时钟、量子测控低温CMOS集成电路。 高速车地通信系统 白勇、李平军团队：研制38GHz高速磁浮交通车地通信系统，保障列车安全可靠运行。 毫米波通信雷达CMOS芯片 樊勇团队与张静直（本人）团队：探索新架构设计。 唐刚海团队：研制超宽带毫米波模块及芯片，用于5G通信与雷达系统。 人才培养成果 连续三年获全国大学生集成电路创新创业大赛奖项。 获华为优秀合作项目奖、研究生优秀导学团队提名奖。 实施“因材施教、科学育人”模式，常态化开展组会、“一对一”指导。 学生在“互联网+”、国际H.O.E.赛事中屡获奖项，毕业生进入华为、中兴、各大研究所及海外深造。 研究方向介绍：物理电子学 学科定义与范畴 物理电子学是物理学与电子科学技术的交叉学科，将物理最新成果应用于电子器件研制。 典型分支包括：微波电子学（产生微波器件）、光电子学（光电器件）、太赫兹电子学、量子电子学。 学科特点：基础性强、前沿性突出、数理要求高，是支撑现代信息技术的关键学科。 我校研究特色 侧重微波电子学，对应微波电真空器件，如回旋管、行波管、磁控管，处于国际先进水平。 起源于1956年电子器件专业，在刘盛纲院士带领下发展高能电子学研究所，2001年成立物理电子学院，2018年并入现学院。 近70年发展实现“纵向+横向”拓展： 纵向：向上游延伸至仿真设计与材料，开发具有自主知识产权的商用软件MMST、QPIEKE；引入人工智能优化设计。 向下游延伸至系统应用，研制毫米波雷达、无线输能系统、微波干燥系统。 横向：向毫米波、太赫兹频段拓展；与医学交叉，开展太赫兹成像用于医学诊断。 科研平台与影响力 拥有1个国家级实验室、3个教育部重点实验室、3个四川省工程中心或重点实验室。 年科研经费近2亿元，为学院最高。 国际上为最大真空器件研究中心之一，2023年成功举办行业顶级会议IVEC（International Vacuum Electronics Conference）于成都。 研究团队与学生出口 共9个科研团队，具体信息可查学院官网。 团队学生毕业去向：约三分之一硕博连读，三分之一进入企业，三分之一进入研究所，其余进入公务员等岗位。 导师个人近三年毕业生去向示例： 2023年：1人赴新疆做博士后，1人进入前沿实验室，1人进入高校 2022年：1人入职华为，1人进入8511研究所 2021年：1人硕博连读，1人考取公务员 学生视角分享：选择电子科大的理由 城市与产业优势 成都为国家中心城市、新一线城市，电子信息产业发达，为全国三大电子工业基地之一。 2025年规上工业产值达3298.9亿元，位居全国前列。 汇聚英特尔、华为、京东方等行业巨头，提供丰富实践与就业资源。 学校定位与学科实力 985高校中唯一以电子信息为核心，被誉为“中国民族电子工业摇篮”。 拥有电子信息博物馆，记录我国首台晶体管收音机诞生。 构建最完整的电子信息学科群，走出大批行业领军者与顶尖学者。 专业选择依据 电子科学与技术学科全国评估A+，五大国防特色学科底蕴深厚。 教师团队实力强，为学生发展提供坚实支撑。 导师与团队选择建议 建议基于研究方向契合度，选择“志同道合、正能量、经费足、就业好”的导师团队。 以毫米波技术与系统应用团队为例： 研究方向覆盖电磁场、电路、系统、芯片、封装等全流程 可开展从算法仿真到FPGA/ARM硬件实现的完整训练 鼓励国际化交流，支持参加国际会议、联合培养 硕博毕业生就业率达100%，进入知名企业与顶尖科研机构 校园生活与奖助体系 校园兼具硬核科研与人文气息，拥有湿地公园、东湖钢琴小屋等设施。 跨年无人机灯光秀以300架无人机拼出“UESTC”字样，体现科技与浪漫融合。 奖助体系全覆盖、高额度、长周期，含国家奖学金、学院奖学金、专项奖学金、新生奖学金及助学贷款，保障基本生活质量。 择校建议 建议通过学院官网了解四大方向、19个科研团队，按兴趣筛选。 利用HBOE、知网等检索导师论文与学生毕业情况，深入了解研究方向。 通过邮件附简历联系意向导师，确认招生意向。 关注夏令营、优秀本科生选拔、预推免等机会，提前实地交流。 招生咨询与互动信息 夏令营安排 2024年将举办夏令营，具体时间待定。 建议感兴趣考生加入QQ群获取最新通知。 直播互动与抽奖 抽奖口令：“一生一世，逐梦未来” 奖品为学院定制马克杯套装，含杯、盖、勺，印有“电子飞蛋”Logo。 中奖观众需私信后台提供联系方式与收货地址。 AI洞察 学院已形成“材料—器件—电路—系统”全链条创新能力，尤其在微波、太赫兹、真空电子等方向具备不可替代的国家战略地位。 多位教师团队成果实现从基础研究到军工应用再到产业化的闭环，体现极强的技术转化能力。 学生培养注重“科研+工程+人文”三位一体，既强调硬核技术训练，也关注综合素质与职业发展。 待办 安排并公布电子学院夏令营的具体时间与形式，并通过QQ群发布相关信息 章节 00:00:41 学院发展历程与院系调整 发言人介绍了电子科学与工程学院的发展历程，包括1956年建校初期的无线电相关院系设立，以及1979年、1992年、2001年和2018年四次重要的院系调整。2023年，为响应国家号召，学院进一步整合成立了电子科学与工程学院与基层电力学院，展示了学院在国家战略背景下的持续发展与变革。 00:01:09 电子科学与技术学科建设情况 介绍了电子科学与技术作为国家重点一级学科的基本情况，包含五个二级学科方向：电磁场与微波技术、电路与系统、微电子学与物理电子学、物理电子学、电子信息功能材料与机构。同时提及三个国防特色学科：电磁场与微波、军用关键材料、电子元器件，突出其在国防与科技发展中的重要地位。 00:01:47 党建与人才培养成果 汇报了学院在党建工作方面取得的成绩，包括入选教育部首批全国党建工作标杆院系，荣获全国教育系统先进集体称号。本科生招生规模为1545人，专业为工科试验班和电子工程类，涵盖国家特色专业和国家级一流本科专业。研究生现有1975人，涵盖学硕、专硕及博士项目，深造率稳定提升，创新创业成绩显著。 00:03:21 师资队伍与科研团队建设 介绍学院教职工总体构成，现有教师302人，其中教研系139人，科研系95人，教学系14人，实验系21人，机关人员33人。师资队伍中包括两院院士2人、领军人才19人、青年人才28人，合计61名高层次人才。拥有两个全国高校黄大年式教师团队，并获批四个国家自然科学基金委创新群体。 00:04:22 科研经费与成果产出 近五年科研到账经费稳定在3~4亿元，以纵向项目为主、横向为辅。牵头获得国家科技奖励11项，发表高水平论文2000余篇，申请专利1600余件，授权1300余件。共有20个科研团队，其中15个年度经费超千万元，一个团队过亿元，体现了强大的科研实力和持续创新能力。 00:05:08 科研平台与技术创新体系 科研方向覆盖材料、器件、电路系统的完整链条，频率范围从射频、微波、毫米波至太赫兹。已形成从基础研究到工程实践再到产业化的全链条创新体系。拥有两个国家级平台：国家电子辐射控制材料工程技术研究中心和电磁薄膜与集成器件全国重点实验室，另有四个国际合作平台和七个省部级科研平台。 00:05:52 国际交流与合作办学 在国际交流方面，学院与香港大学电机工程电子系、武汉城市大学电子工程系共建国际联合院系。主办高水平国际会议13场，开展学生长短期交流项目20余个，推动国际化人才培养与学术合作，提升学院的全球影响力。 00:06:24 电子信息材料与元器件研究方向介绍 详细介绍了电子信息材料与元器件方向的研究内涵，强调‘一代材料催生一代器件，服务一代整机’的核心理念。该方向聚焦电子材料与器件的设计、研制与应用，面向我国集成电路等‘卡脖子’问题，在6G通信、量子技术、智慧城市等领域具有重大战略意义。市场预计2025年将达到万亿美元量级。 00:10:35 重点科研团队与国家级平台支撑 该方向依托邓龙江院士领衔的电磁辐射控制材料与技术团队（19人）和张怀武教授领导的实践薄膜微型器件团队（17人），承担国家重点研发计划、自然基金重大项目百余项。拥有国家电子辐射控制材料工程技术研究中心和电磁薄膜与集成器件全国重点实验室两大国家级平台，科研面积超2万平方米，具备完整的材料-器件-系统全链条研发能力。 00:15:47 研究成果与毕业生发展去向 研究成果丰硕，近年在《自然》系列期刊发表多篇论文，获国家科技奖项七项。毕业生广泛就职于英特尔、中芯国际、华为、中国电科等行业龙头企业及国内外高校科研院所。多位优秀学生代表在磁性材料、5G滤波器芯片、MEMS器件等领域取得突出成就，展现了卓越的科研与产业化能力。 00:18:49 电磁场与微波技术及电路系统专业介绍 系统介绍电磁场与微波技术学科的历史沿革（始于1956年）、师资力量（国家级人才19人）、六个主要研究团队及其成果，涵盖天线理论、毫米波系统、电磁兼容等方向。同时介绍电路与系统学科作为国内首批博硕士点的发展历程，拥有教育部国际合作联合实验室，聚焦非线性电路、射频微波与集成电路三大方向。 00:21:45 代表性科研成果与技术突破 多个团队取得关键技术突破：杨世文教授团队在四维天线阵列、强耦合超宽带相控阵方面成果应用于中电十四所雷达系统；樊勇教授团队在毫米波平面天线、太赫兹雷达成像系统（分辨率小于1厘米）方面取得进展，并在成都大运会示范应用；李岩教授团队在微波测量技术上打破国外封锁；闫波教授团队实现毫米波导引头前端等多项系统集成突破。 00:25:43 人才培养成效与就业前景 在人才培养方面连续三年获得全国大学生集成电路竞赛奖项，荣获华为优秀合作项目奖。实施因材施教、育德为先的培养模式，常态化开展组会与一对一指导。毕业生广泛进入华为、中兴等领军企业及各大研究所，海外深造亦有突破，整体就业领域分布广泛且质量高。 00:31:30 物理电子学学科内涵与发展现状 物理电子学是物理学与电子科学技术交叉的前沿学科，涵盖微波电子学、光电子学、量子电子学等多个分支。我校侧重微波电子器件研究，在回旋管、行波管、磁控管等领域达到国际先进水平。起源于1956年电子器件专业，历经高能电子学研究所、物理电子学院等发展阶段，现为电子科学与工程学院的重要组成部分。 00:35:45 科研拓展方向与平台优势 近年来向上下游延伸发展：上游推进仿真设计与人工智能融合，推出具有自主知识产权的商用软件MMST与Qpic；下游拓展至毫米波雷达、无线输能、微波干燥等系统应用。横向发展至太赫兹技术与医学交叉，在太赫兹成像、保密通信等方面取得进展。拥有1个国家重点实验室、3个教育部重点实验室，年科研经费近2亿元，是国际最大的真空器件研究中心之一。 00:38:55 学生培养与职业发展路径 物理电子学方向共有9个科研团队，学生毕业去向均衡：约三分之一继续攻读博士学位，三分之一进入企业，三分之一进入研究所或从事公务员工作。近三年毕业生去向包括华为、8511研究所、高校及前沿实验室，体现了多元化的高质量发展路径。 00:40:21 学生视角下的择校与专业选择建议 博士生田雨桐从个人经历出发，分享选择电子科大的八大理由：城市优势（成都作为电子信息产业基地）、学校行业地位（985中唯一专注电子信息的高校）、学科实力（电子科学与技术A+）、导师匹配、科研平台、国际化机会、校园生活与奖助体系。建议新生通过学院官网、文献检索等方式深入了解意向导师，并积极参与夏令营等交流活动。 00:47:53 夏令营信息与直播互动环节 主持人询问关于学院夏令营的具体安排，发言人回应今年将举办夏令营，具体时间待定，鼓励感兴趣的同学加入QQ群获取最新信息。随后进行直播抽奖环节，公布口令“一生一世，逐梦未来”，并在弹幕中抽取幸运观众赠送学院定制马克杯套装，增强观众参与感与互动氛围。 | L3: 5 | M3: 3 | N3: 4 | O3: 0 | P3: =(L3+M3+N3)/3 -> 4 | Q3: 2.1 核心遗漏： QQ群群号没有提及 2.2 比例失调：介绍发展历程、博士生成果的篇幅过长 2.3 冗余：没有对博士生的成果进行有效概括 3.2 小标题合理性：择校建议标题与学院信息介绍的主题不符 | R3: 学院概况 历史沿革： 初期成立无线电系、电真空器件系、无线电零件系。 历经1979年、1992年、2001年、2018年四次院系调整，成立电子科学与工程学院、科辅示范性微电子学院。 2023年响应国家号召，成立电子科学与工程学院与基层电路学院。 学科建设： 一级学科：电子科学与技术（国家重点一级学科）。 二级学科方向：电磁场与微波技术、电路与系统、微电子学与固体电子学、物理电子学、电子信息功能材料与机构。 国防特色学科：电磁场与微波、军用关键材料、电子元器件。 党建荣誉： 学校党委入选教育部首批全国党建工作标杆院系。 学院荣获全国教育系统先进集体。 人才培养 本科生： 现有1545人。 招生专业：工科实验班电子。 工程类专业方向：电子科学技术（国家特色专业、国家级一流本科专业建设点）、电磁场与无线技术。 研究生： 现有硕士和博士研究生1975人。 招生专业： 学术学位：博士（电子科学与技术）、硕士（电子科学与技术、材料科学与工程）。 专业学位：博士（电子信息）、硕士（电子信息材料工程）。 培养成果： 荣获国家级教学成果奖二等奖5项。 本科生深造率稳中有进。 创新创业竞赛屡创佳绩。 研究生科研学术能力不断加强，就业布局不断优化。 涌现出许多优秀个人和集体，获得代表性的党建、思政荣誉等。 所获荣誉：连续三年获得全国大学生集成电路创新创业大赛奖项，荣获华为优秀合作项目奖，荣获研究生优秀导学团队提名奖，获互联网加奖项、国际上IETF奖项、优秀论文、创新创业大赛成果奖项等。 培养模式：因材施教，科学育人，宗旨是育才先育德，师生齐共建，常态化开展学术组会及三个一对一的面对面等体系化、规范化、国际化的培养模式。 就业情况：就业领域分布广泛，包括行业领军企业（如华为、中兴等）、各大研究所、高校，毕业生在海外留学方面也有不少突破。 教职工构成与师资队伍 教职工总体构成： 现有教师302人，其中教研系139人、科研系95人、教学系14人、实验系21人，教师总数269人，机关33人。 师资队伍： 两院院士2人。 领军人才19人。 青年人才28人。 其他类型人才12人。 后备人才61人。 荣获两个全国高校黄大年式教师团队：太赫兹科学技术研究中心教师团队（2018年）、电池辐射与膳食教师团队（2022年）。 融合4个国家自然科学基金为创新群体。 科研情况 科研经费：近5年科研到账经费稳定在3~4亿元之间，项目构成以纵向项目为主，横向项目为辅。 科研成果： 牵头获得国家科技奖励11项。 近5年发表高水平学术论文2000余篇。 专利申请1600余件，授权1300余件。 科研团队： 共20个科研团队。 年度经费过千万元的团队15个，其中过亿元团队1个。 科研方向： 材料、器件、电路系统形成完整学术链条。 频率范围覆盖射频、微波、毫米波、太赫兹等高频段。 形成从基础科学研究到工程实践再到产业化的一条龙创新体系。 科研平台： 国家级平台2个：国家电子辐射控制材料工程技术研究中心、微波电真空器件国家级重点实验室。 国际合作平台4个。 省部级科研平台7个。 国际交流 共建国际姊妹院系2个：香港大学电机工程电子系、香港城市大学电子工程系。 主办高水平国际会议13场。 学生长短期交流项目20多个。 专业方向介绍 电磁场与微波技术 细分方向：微波、毫米波电路；电波传播与电磁兼容；计算电磁学与工程电子学；天线理论与技术。 历史沿革：始于1956年电子科技大学建校时期，由林为干先生和谢处方先生共同创建。 专业特色：电子场与无线技术国家特色级专业；电波传播与天线、国防紧缺特色专业。 所属一级学科：电子科学与技术，入选双一流A类学科。 师资队伍：国家级人才计划入选者19人，其他众多中青年优秀师资，研究方向涵盖本学科所有主流方向。 研究团队：电磁辐射与散射团队、毫米波技术与系统应用团队、微波毫米波集成电路与系统团队、电磁兼容技术团队、微波测试与成像技术团队、无线技术与集成系统团队。 学科平台：国家自然科学基金委创新群体、国家高等学校学科创新引智基地、国家工程技术研究中心、国家级重点实验室。 硬件平台：中国高校最为先进的微波暗室群体，先进的微波、毫米波、太赫兹仿真测试平台。 主要研究成果 天线理论与技术：杨士文教授团队研究四维天线阵列技术，提供新自由度，实现低成本、高性能，提升系统整体性能；杨士莪教授团队在强耦合、超宽带相控阵方面取得进展，应用成果用于中电十四所某大型机载相控阵雷达；樊勇教授团队研究毫米波平面集成天线，可应用于毫米波通信、雷达系统领域，为新一代毫米波前端平面化集成化奠定基础。 电波传播与电磁兼容：李恩教授团队引领的微波毫米波测量技术，突破众多技术封锁，有60多年技术积累和传承；杨世文教授团队在电磁测井仪器方面研究获国家科技进步二等奖，成果在中海油成功推广应用。 微波毫米波电路：闫波教授团队引领微波、毫米波、太赫兹芯片研究，获国家科技重大专项及军科委相关项目，应用于新一代高速通信系统；在微波毫米波器件与系统方面取得突破，成果可应用于大功率合成功放、固态合成功率源、天线阵列、馈电网络等电路与通信雷达系统；在微波毫米波微系统技术方面取得进展，包含3毫米导引头前端、毫米波引信前端、8毫米宽带收发前端。 计算电磁学与工程电磁学：杨世文教授团队引领的计算电磁学研究取得重要成果，相关算法被评为20世纪十大算法之一；樊勇教授团队在太赫兹雷达成像方面取得进展，成功研制0.22太赫兹、0.34太赫兹、0.42太赫兹雷达成像系统实验平台，分辨率小于1厘米；同时在太赫兹通信技术方面有突破，成果在2023年成都大运会田径项目中成功示范应用；李岩教授团队在电磁波与物质互作用机理及测评系统方面，面向5G通信、高性能系统、生物医学、新能源等方向提供应用需求和研究成果；李恩教授团队在生物医学电磁学及成像方向取得进展，发表大量高水平论文，有20余项国家发明专利。 电路与系统 细分方向：非线性电路与复杂电子系统、射频微波电路与系统、集成电路与系统。 学科地位：国内首批授予硕士、博士学位的学科（1981年开始招收研究生、博士研究生），1988年成立首批博士后流动站。 学科平台：教育部国际合作联合实验室、国家高等学校学科创新引智基地。 师资队伍：国家级人才4人、新世纪人才2人、教授10人、副教授22人。 主要研究方向与成果 集成物理研究方向：樊勇教授和王成教授团队，聚焦CMOS集成电路与物理结合的前沿交叉学科领域，研制相关芯片及分子时钟、量子测控低温CMOS集成电路。 高速车地通信系统：白勇教授和李庭军教授团队，从事高速磁浮交通的38G赫兹车地通信系统研制，是高效、经济和安全的交通技术，实现安全、可靠、实时、宽带等，确保列车安全运行和基本保障。 毫米波通信雷达CMOS芯片：樊勇教授团队和张静植（本人）研究团队，面向通讯与雷达领域的新应用、新场景、新应用，探索集成电路设计的新架构；康康凯教授团队在毫米波CMOS芯片方向取得进展，包括超宽带的毫米波模块级芯片以及5G通信系统和雷达系统的研制。 电子信息材料与元器件方向介绍 方向定位：涉及电子材料与电子器件，是IT领域的物质基础与先导，推动电路系统与电子装备研发，概括为“一代材料催生一代器件，服务一代整机”。 内涵：以电子在物质中的输运特性（电磁、声、光、热力、化学生物类比特性）及外部作用为基础，设计、研究和生产电子器件，并在电路、电子系统乃至整机中实现工程应用，推动电子信息技术发展，涉及电子材料、器件、电路的设计研制、生产和应用，以材料为基础、器件为核心、应用为目标导向。 国家需求与市场： 中国是电子产品生产大国但非强国，2021年中国集成电路等电子产品进口额度达2.8万亿元，约为原油进口量的1.7倍，反映先进电子材料、元器件等是我国“卡脖子”问题之一。 电子产品在6G通讯、量子技术、智慧城市、光电技术、新能源、智能电子等领域作用重要，是国民经济关键支撑，广泛应用于物联网、移动设备、网络基础设施、无人驾驶、航空航天、医疗健康、可穿戴设备等领域。 预计2025年整个电子产品市场额度将达到万亿美元量级。 发展趋势： 电子产品向小型化、多功能、低功耗、智能化方向发展。 元器件朝着微型化、片式化、集成化、薄膜化和智能化方向发展，尤其强调材料和器件一体化。 集成技术发展趋势是结合摩尔定律制成缩小与超摩尔定律功能多样化，通过三维集成的微系统实现价值整合，通过介电、铁电、压电、磁性、半导体等功能材料的结构复合与功能集成，实现信息获取与处理，形成新一代信息技术物质形态或半导体技术物理载体的固态电子薄膜。 研究队伍： 包括国家级人才十余人。 邓龙江院士团队（电磁辐射控制材料与技术团队）：现有研究人员19人（正高13人，副高15人），重点开展可见光、红外、微波等频段电子辐射控制材料、结构和器件研究；发表Nature子刊等论文300余篇，承担国家省部级及国际合作课题130余项，年均到账经费3000多万元，授权专利100余项，获国家科技进步或技术发明奖二等奖共计3项。 张怀武教授团队（实电波膜与微型器件团队）：现有研究人员17人（正高15人，副高2人），重点开展LTCC材料及集成技术、微波毫米波晶圆及器件、自旋电子与磁量子器件、传感器芯片等研究；承担国家重点研发计划、自然基金重点、重大科学仪器项目及国际合作等项目100余项，获国家技术发明或科技进步二等奖共计3项，发表SCI论文400余篇，年均到账经费2000万元。 依托平台： 国家电子辐射控制材料工程技术研究中心：历史追溯至1990年校级材料与技术研究中心，经2008年、2013年两次升级形成；主要开展多频谱涂层电池材料与结构、智能材料与结构研究；拥有国际一流实验平台及成都佳驰电子科技等成果转化基地。 电磁薄膜与集成器件全国重点实验室：2006年依托新型传感器功率半导体技术、电子信息材料三个部级重点实验室筹建；结合电子信息系统微小型化和单片集成重大需求，围绕电子薄膜材料和集成器件开展基础、应用基础、工程应用研究；重点方向为磁电薄膜与微型器件、电子聚合物与阵列传感器、功率半导体与集成技术。 研究条件： 科研面积2万余平米，超净间3000平。 建设两条国家重大任务试验生产线。 拥有大型设备或系统500余台套，构建材料、器件、电路系统全链条研究平台，实现测试表征全覆盖。 材料制备：拥有各类液相外延、磁控溅射、化学气相沉积、分子外延、原子沉积等薄膜材料制备设备50余台套。 微细加工：拥有步进式光刻机、深槽反应离子刻蚀机等先进微纳加工设备30台套，具备电子功能薄膜微图形化加工能力，形成较完善的亚微米集成器件、非CMOS工艺实验线。 材料结构分析：拥有X射线衍射仪、粒度分析仪、X射线光电子能谱仪、扫描电镜、扫描探针显微镜、透射电镜等微观表征设备10余台套。 材料器件性能测试：拥有浪漫光谱、阻抗分析仪、分光光度计、差热分析仪、傅里叶红外光谱等材料性能测试设备50余台套。 研究成果： 高水平论文：在《自然》及其子刊近年来每年有多篇重要文章发表。 奖项：获得包括国家科技、国家技术发明奖共计7项。 毕业生去向：遍布产业界与学术界，包括英特尔、中芯国际、华为、德州仪器、中国电科等世界500强企业，以及国内外高校和科研院所，成为学术牛人、技术大拿、创新创业能手，在前沿基础研究、军工项目研发、产品技术开发等方向贡献突出。 优秀毕业生代表： 杨伟豪同学：在磁性非互易表面研究领域成果显著，以第一作者在《自然·电子》《自然·通讯》各发表一篇学术论文。 5G滤波器芯片学生团队：获挑战杯创新创业大赛四川省金奖。 黄飞：2018年四川省优秀毕业生，获斯坦福大学攻读博士全额奖学金。 李凤霞：早期优秀毕业生代表，读博期间发表学术论文16篇，其中一作6篇。 闫威：2021届优秀毕业生，2020年获华为光产线优秀合作项目奖，2021年获王大珩光学奖，博士毕业后以优秀青年学者身份加入苏州大学。 汪卫：产业界优秀毕业生代表，河北美泰电子科技公司副总，率先带领团队采用MEMS工艺研制出SiW环形器隔离器，突破卡脖子器件核心技术，实现高性能非互易器件产业化。 物理电子学学科介绍（李天明老师） 学科定义及范畴： 物理电子学是物理学与电子科学技术的交叉学科。 物理学研究物质能量的本质与性质；电子科学与技术研究电子在不同介质中的运动规律和与物质的相互作用，并据此研制电子器件。 结合方式：将物理学最新研究成果应用于电子学，产生新的电子器件。 典型分支及器件： 微波与电子相互作用 → 微波电子学 → 微波电真空器件。 光与电子相互作用 → 光电子学 → 光电器件。 维拉技术与电子学结合 → 维拉电子学。 量子技术与电子学结合 → 量子电子学。 学科特点： 内容不断充实（如量子电子学内容因量子技术发展而增加）。 学科边界不一定清晰，归类不一定完整（如光电子学既可属物理电子学，也可属光学工程一级学科）。 基础性与前沿性：强调数理基础，应用物理最新研究成果，具有应用前沿性。 重要性：支撑现代信息技术的关键技术学科，其电子器件是信息科技产业的重要组成部分。 学校的物理电子学： 侧重点：微波电子学，对应微波电真空器件（产生微波的器件）。 微波应用：在通信、雷达等领域应用广泛。 传统强项：回旋管、行波管、磁控管研究，达到国际先进水平。 发展历程： 1956年建校时，在前苏联专家帮助下成立电子工器件专业，归属电子器件系。 1979年，在刘盛纲院士带领下成立高能电子学研究所，专业并入该所。 2001年，物理系应用所、高能所合并成立物理电子学院。 2018年，物理电子学院与电工学院、微固学院部分合并成立电子科学与工程学院，现属电子科学与工程学院下的专业。 学科内涵扩展： 纵向发展： 上游：仿真设计、数字模拟、材料。推出两款具有自主知识产权的商用软件：MMSD、Chepico（国内广泛应用）。将人工智能引入器件设计和电子学应用。 下游：系统应用。例如：利用回旋行波管研制毫米波雷达；利用行波管做无线速能系统；利用磁控管做微波炉干燥系统。 横向发展： 频段上移：从微波到毫米波、太赫兹。 与其他学科深入交叉（如医学）： 太赫兹技术：太赫兹成像（分辨率高、透视效果好）、光电融合新太赫兹源、太赫兹保密通信与高速通讯。 医学应用：太赫兹成像应用于医学诊断，提高诊断准确性。 科研平台与成果： 科研平台：国家级实验室、三个教育部重点实验室、三个四川省工程中心或重点实验室，参与一系列行业协会。 成果：一系列国家奖、省奖；每年到校科研经费接近两个亿（学院内最多）；是国际上最大的真空器件研究中心之一，名气日益增大；2023年成功举办行业顶级会议IVEC（成都）。 团队与学生出口（李天明团队为例）： 团队：物理电子学方向共有9个团队（详情可查询学院网页）。 学生出口（团队情况）：1/3硕博连读，1/3去企业，1/3去研究所及其他（如公务员）。 李天明个人学生情况：每年约2名研究生、1名博士毕业。 近三年研究生去向：今年2人当公务员；去年1人去华为，1人去8511研究所；前年1人硕博连读，1人去私企。 近三年博士去向：今年1人去新加坡做博后，1人去前沿实验室，1人去高校。 选择电子学院的理由及研究生择校专业选择建议（田雨彤同学） 选择电子学院的8个理由（学生视角）： 城市因素： 成都：四川省会、国家中心城市、新一线城市，国家历史文化名城，古蜀文明发祥地，中国十大古都之一。 城市标语“成都都成”（梦想都成），体现古老文化底蕴与年轻科技活力。 电子信息产业发达：全国三大电子工业基地之一，构建电子信息全产业链体系，2025年规上工业产值达3298.9亿元，位居全国前列。 产业资源：英特尔、华为、京东方等众多行业巨头汇聚，提供实践平台和就业资源。 学校因素： 电子科技大学是985高校中唯一以电子信息科学技术为核心的院校。 网络评价：“走在路上都能捡到电阻等元器件”。 拥有电子信息博物馆，记录我国第一台晶体管收音机诞生。 构建了最完整的电子信息学科群（电子科学与技术、信息与通信工程、集成电路科学与技术等）。 中国民族电子工业人才摇篮，走出大批行业领军者。 专业因素： 电子学院电子科学与技术学科在第四轮学科评估中斩获A+，稳居全国第一。 拥有五大国防特色学科（如电磁场与微波技术、微电子与固体电子学），构建深厚科研底蕴。 教师团队能提供能力提升帮扶与保障，研究团队实力是学生发展的坚强后盾。 研究团队与导师： 选择标准：研究方向契合，期望志同道合的良师益友，团队正能量、经费足、就业好，能实现个人能力全面提升。 所在团队：毫米波技术与系统应用团队（负责人樊勇老师）。 研究方向：微波毫米波理论与技术、天线理论与技术、元器件与电路、通信技术与系统、雷达成像技术与系统。 知识覆盖：电磁场与微波技术、电路与系统，从芯片、封装、天线、电路模块到系统的全面知识。 科研实践：可根据兴趣和创新想法做雷达或无线通信系统，进行算法开发、硬件制作（基于FPGA、ARM等芯片）和实验室验证。 国际交流：鼓励出国参加国际会议、联合培养。 团队成果：学生发表大量论文，在学术会议竞赛上取得佳绩，获傲人奖项，就业率100%，就业单位包括知名企业和顶尖科研机构。 生活因素： 成电校园：硬核科研与烟火气并存。 休闲活动：湿地公园漫步、草地桌游、东湖边钢琴小屋弹琴。 难忘经历：2021年跨年主楼前300架无人机灯光秀拼出UESTC字样，留下浪漫与科技交织的印象。 奖助体系： 全覆盖、高额度、长周期。 奖学金：国家奖学金、学业奖学金、专项奖学金、新生奖学金及学校学院设立的其他奖学金。 奖助：校园地国家助学贷款、生源地信用助学贷款。 保障：各类奖助能保障求学期间基本生活质量。 研究生择校和专业选择建议： 选择导师： 先根据研究方向选择合适的研究团队，再选择合适的导师。 学院资源：拥有四大学科和19个科研团体，可从学院网站按兴趣选择团队，再进入团队网页找导师。 深入了解导师：若导师信息不完整，可通过HPOE、中国知网等文献检索网站，检索导师论文情况和指导研究生毕业情况，结合兴趣广泛调研。 联系导师：确定意向导师后，通过电子邮件附带简历与个人介绍联系，确定导师招生意向。 推荐关注：学院夏令营优秀本科生选拔计划和推免招生计划，提前来校与老师、师兄师姐沟通交流。 直播互动及后续信息 夏令营活动： 计划举办：电子学院今年计划举办夏令营活动。 时间：待定。 咨询方式：感兴趣的同学可加入QQ群（群号：978499108），相关信息将及时发布。 抽奖活动： 奖品：学校一整套马克杯（有学院学校特色logo，配套勺子和杯盖）。 口令：“一生一世，筑梦未来”（“一”是字母“E”）。 幸运观众：IWN同学、最爱冰粉凉虾同学、一男同学、尾号5240小提琴同学。 领奖方式：私信后台留下联系方式和收货地址。 后续安排 有意参加电子学院夏令营的同学加入QQ群（群号：978499108），以便及时获取夏令营相关信息。 抽奖获得马克杯的幸运同学（IWN、最爱冰粉凉虾、一男、尾号5240小提琴）私信后台留下联系方式和收货地址。 计划申请研究生的同学关注电子学院今年的夏令营优秀本科生选拔计划和推免招生计划。 计划申请研究生的同学可通过学院网站了解四大学科和19个科研团体，选择感兴趣的研究团队和导师。 有意向导师的同学可通过HPOE、中国知网等文献检索网站了解导师研究方向和论文情况。 确定意向导师的同学可通过电子邮件附带简历与个人介绍与导师取得联系，确定导师招生意向。 内容由 AI ⽣成，仅供参考 | S3: 5 | T3: 5 | U3: 5 | V3: 0 | W3: =(S3+T3+U3)/3 -> 5 | X3: 结构性最清晰，小标题最合理，可读性最强
